package com.magicbee.ctnhmana.registry.multiblock;

import com.gregtechceu.gtceu.GTCEu;
import com.gregtechceu.gtceu.api.data.RotationState;
import com.gregtechceu.gtceu.api.machine.MultiblockMachineDefinition;
import com.gregtechceu.gtceu.api.machine.multiblock.RecipeElectricMultiblockMachine;
import com.gregtechceu.gtceu.api.pattern.FactoryBlockPattern;
import com.gregtechceu.gtceu.api.pattern.Predicates;
import com.gregtechceu.gtceu.common.data.GTBlocks;
import com.gregtechceu.gtceu.common.data.GTMachines;
import com.gregtechceu.gtceu.common.data.GTMaterials;

import net.minecraft.ChatFormatting;
import net.minecraft.network.chat.Component;
import net.minecraft.world.level.block.Blocks;

import com.magicbee.ctnhmana.CTNHMana;
import com.magicbee.ctnhmana.client.render.EternalGardenRender;
import com.magicbee.ctnhmana.client.render.ManaCondenserRender;
import com.magicbee.ctnhmana.common.multiblock.EternalGarden;
import com.magicbee.ctnhmana.common.multiblock.ManaCondenserMachine;
import com.magicbee.ctnhmana.common.parts.CMPartsAbility;
import com.magicbee.ctnhmana.registry.CMBlocks;
import com.magicbee.ctnhmana.registry.CMRecipeTypes;
import io.github.lounode.extrabotany.common.block.ExtraBotanyBlocks;
import vazkii.botania.common.block.BotaniaBlocks;
import vazkii.botania.common.block.BotaniaFlowerBlocks;

import static com.gregtechceu.gtceu.api.GTValues.EV;
import static com.gregtechceu.gtceu.common.data.GTBlocks.*;
import static com.gregtechceu.gtceu.common.data.models.GTMachineModels.createWorkableCasingMachineModel;
import static com.hollingsworth.arsnouveau.setup.registry.BlockRegistry.*;
import static com.hollingsworth.arsnouveau.setup.registry.BlockRegistry.VEXING_LOG;
import static com.magicbee.ctnhmana.CTNHMana.REGISTRATE;
import static com.magicbee.ctnhmana.registry.CMBlocks.*;
import static net.minecraft.world.level.block.Blocks.*;
import static net.minecraft.world.level.block.Blocks.WATER;

public class Botania {

    public static void init() {}

    public final static MultiblockMachineDefinition ETERNAL_GARDEN = REGISTRATE.multiblock("eternal_garden",
            EternalGarden::new)
            .rotationState(RotationState.NON_Y_AXIS)
            .allowFlip(false)
            .cnLangValue("芙蕾雅的永恒花园")
            .recipeType(CMRecipeTypes.ETERNAL_GARDEN)
            .recipeModifiers(EternalGarden::recipeModifier)
            .tooltips(Component.translatable("ctnh.multiblock.eternalgarden.tooltip.1"),
                    Component.translatable("ctnh.multiblock.eternalgarden.tooltip.2"),
                    Component.translatable("ctnh.multiblock.eternalgarden.tooltip.broadcast"),
                    Component.translatable("ctnh.multiblock.eternalgarden.tooltip.3"),
                    Component.translatable("ctnh.multiblock.eternalgarden.tooltip.unknown"))
            .pattern(definition -> FactoryBlockPattern.start()
                    .aisle("A###################BBBBBBB###################A",
                            "####################BBBBBBB####################",
                            "####################BBBBBBB####################",
                            "###############################################",
                            "###############################################",
                            "###############################################",
                            "###############################################",
                            "###############################################",
                            "###############################################",
                            "###############################################",
                            "###############################################",
                            "###############################################",
                            "###############################################",
                            "###############################################",
                            "###############################################",
                            "###############################################",
                            "###############################################",
                            "###############################################",
                            "###############################################",
                            "###############################################",
                            "###############################################",
                            "###############################################",
                            "###############################################",
                            "###############################################",
                            "###############################################",
                            "###############################################",
                            "###############################################",
                            "A#############################################A")
                    .aisle("#################BBBBBBBBBBBBB#################",
                            "#################BBBBBBBBBBBBB#################",
                            "#################BBBBBBBBBBBBB#################",
                            "###############################################",
                            "###############################################",
                            "###############################################",
                            "###############################################",
                            "###############################################",
                            "###############################################",
                            "###############################################",
                            "###############################################",
                            "###############################################",
                            "###############################################",
                            "###############################################",
                            "###############################################",
                            "###############################################",
                            "###############################################",
                            "###############################################",
                            "###############################################",
                            "###############################################",
                            "###############################################",
                            "###############################################",
                            "###############################################",
                            "###############################################",
                            "###############################################",
                            "###############################################",
                            "###############################################",
                            "###############################################")
                    .aisle("###############BBBBBBBBBBBBBBBBB###############",
                            "###############BBBBBBBBBBBBBBBBB###############",
                            "###############BBBBBBBBBBBBBBBBB###############",
                            "######################CCC######################",
                            "###############################################",
                            "###############################################",
                            "###############################################",
                            "###############################################",
                            "######################DDD######################",
                            "####################EFEGEFE####################",
                            "####################G#GHG#G####################",
                            "####################EGEFEGE####################",
                            "######################DDD######################",
                            "###############################################",
                            "###############################################",
                            "###############################################",
                            "###############################################",
                            "###############################################",
                            "###############################################",
                            "###############################################",
                            "###############################################",
                            "###############################################",
                            "###############################################",
                            "###############################################",
                            "###############################################",
                            "###############################################",
                            "###############################################",
                            "###############################################")
                    .aisle("#############BBBBBBBBBBBBBBBBBBBBB#############",
                            "#############BBBBBBBBBBBBBBBBBBBBB#############",
                            "#############BBBBBBBIIBBBIIBBBBBBB#############",
                            "######################CJC######################",
                            "#######################J#######################",
                            "#######################J#######################",
                            "#######################J#######################",
                            "#######################J#######################",
                            "######################DJD######################",
                            "#################FEGKKKJKKKGEF#################",
                            "##################G#HHHJHHH#G##################",
                            "#################GEFKKKJKKKFEG#################",
                            "######################KLK######################",
                            "###############################################",
                            "###############################################",
                            "###############################################",
                            "###############################################",
                            "###############################################",
                            "###############################################",
                            "###############################################",
                            "###############################################",
                            "###############################################",
                            "###############################################",
                            "###############################################",
                            "###############################################",
                            "###############################################",
                            "###############################################",
                            "###############################################")
                    .aisle("###########BBBBBBBBBBBBBBBBBBBBBBBBB###########",
                            "###########BBBBBBBBBBBBBBBBBBBBBBBBB###########",
                            "###########BBBBBBIIIBBBBBBBIIIBBBBBB###########",
                            "######################CMC######################",
                            "###############################################",
                            "###############################################",
                            "###############################################",
                            "###############################################",
                            "####################NNNNNNN####################",
                            "###############GEKKK#######KKKEG###############",
                            "################GHHH#######HHHG################",
                            "###############FEKKK#######KKKEF###############",
                            "####################NNNNNNN####################",
                            "######################OLO######################",
                            "######################OPO######################",
                            "######################OLO######################",
                            "###############################################",
                            "###############################################",
                            "###############################################",
                            "###############################################",
                            "###############################################",
                            "###############################################",
                            "###############################################",
                            "###############################################",
                            "###############################################",
                            "###############################################",
                            "###############################################",
                            "###############################################")
                    .aisle("#########BBBBBBBBBBBBBBBBBBBBBBBBBBBBB#########",
                            "#########BBBBBBBBBBBBBBBBBBBBBBBBBBBBB#########",
                            "#########BBBBBBIIBBBBBBBBBBBBBIIBBBBBB#########",
                            "#######################N#######################",
                            "###############################################",
                            "###############################################",
                            "###############################################",
                            "###############################################",
                            "#################NNN#######NNN#################",
                            "#############FEKK#############KKEF#############",
                            "##############GHH#############HHG##############",
                            "#############GEKK#############KKEG#############",
                            "#################NNN#######NNN#################",
                            "######################HHH######################",
                            "######################HJH######################",
                            "######################HHH######################",
                            "######################KLK######################",
                            "######################KLK######################",
                            "###############################################",
                            "###############################################",
                            "###############################################",
                            "###############################################",
                            "###############################################",
                            "###############################################",
                            "###############################################",
                            "###############################################",
                            "###############################################",
                            "###############################################")
                    .aisle("########BBBBBBBBBBBBBBBBBBBBBBBBBBBBBBB########",
                            "########BBBBBBBBBBBBBBBBBBBBBBBBBBBBBBB########",
                            "########BBBBBIIBBBBBBBBBBBBBBBBBIIBBBBB########",
                            "#######################N#######################",
                            "###############################################",
                            "###############################################",
                            "###############################################",
                            "###############################################",
                            "###############NN#############NN###############",
                            "###########GEKK#################KKEG###########",
                            "############GHH#################HHG############",
                            "###########FEKK#################KKEF###########",
                            "###############NN#############NN###############",
                            "######################HHH######################",
                            "######################HJH######################",
                            "######################HHH######################",
                            "###############################################",
                            "###############################################",
                            "######################KLK######################",
                            "######################KLK######################",
                            "###############################################",
                            "###############################################",
                            "###############################################",
                            "###############################################",
                            "###############################################",
                            "###############################################",
                            "###############################################",
                            "###############################################")
                    .aisle("#######BBBBBBBBBBBBBQQQLQQQBBBBBBBBBBBBB#######",
                            "#######BBBBBBBBBBBBB###L###BBBBBBBBBBBBB#######",
                            "#######BBBBIIBBBBBBB###L###BBBBBBBIIBBBB#######",
                            "#######################N#######################",
                            "###############################################",
                            "###############################################",
                            "###############################################",
                            "###############################################",
                            "#############NN#################NN#############",
                            "##########EKK#####################KKE##########",
                            "##########GHH#####################HHG##########",
                            "##########EKK#####################KKE##########",
                            "#############NN#################NN#############",
                            "######################HHH######################",
                            "######################HJH######################",
                            "######################HHH######################",
                            "###############################################",
                            "###############################################",
                            "###############################################",
                            "###############################################",
                            "######################KLK######################",
                            "######################KLK######################",
                            "###############################################",
                            "###############################################",
                            "###############################################",
                            "###############################################",
                            "###############################################",
                            "###############################################")
                    .aisle("######BBBBBBBBBBBQQQRRRLRRRQQQBBBBBBBBBBB######",
                            "######BBBBBBBBBBB###SSS#SSS###BBBBBBBBBBB######",
                            "######BBBBBBBBBBB#############BBBBBBBBBBB######",
                            "########DCC#########################CCD########",
                            "###############################################",
                            "###############################################",
                            "###############################################",
                            "###############################################",
                            "#########DDNN#####################NNDD#########",
                            "#########HK#########################KH#########",
                            "#########GH#########################HG#########",
                            "#########HK#########################KH#########",
                            "#########DDNN#####################NNDD#########",
                            "######################HHH######################",
                            "######################HJH######################",
                            "######################HHH######################",
                            "###############################################",
                            "###############################################",
                            "###############################################",
                            "###############################################",
                            "###############################################",
                            "###############################################",
                            "######################KLK######################",
                            "###############################################",
                            "###############################################",
                            "###############################################",
                            "###############################################",
                            "###############################################")
                    .aisle("#####BBBBBBBBBBQQRRRHHHLHHHRRRQQBBBBBBBBBB#####",
                            "#####BBBBBBBBBB##SSS#######SSS##BBBBBBBBBB#####",
                            "#####BBBBBBBBBB#################BBBBBBBBBB#####",
                            "########CTC#########################CTC########",
                            "#########T###########################T#########",
                            "#########T###########################T#########",
                            "#########T###########################T#########",
                            "#########T###########################T#########",
                            "########DTD#########################DTD########",
                            "########HT###########################TH########",
                            "########GT###########################TG########",
                            "########HT###########################TH########",
                            "########DDD#########################DDD########",
                            "######################HHH######################",
                            "######################HJH######################",
                            "######################HHH######################",
                            "###############################################",
                            "###############################################",
                            "###############################################",
                            "###############################################",
                            "###############################################",
                            "###############################################",
                            "###############################################",
                            "######################KLK######################",
                            "###############################################",
                            "###############################################",
                            "###############################################",
                            "###############################################")
                    .aisle("#####BBBBBBBBQQRRHHHHRRLRRHHHHRRQQBBBBBBBB#####",
                            "#####BBBBBBBB##SS####UU#UU####SS##BBBBBBBB#####",
                            "#####BBBBBBBB#####################BBBBBBBB#####",
                            "########CCD#########################DCC########",
                            "###############################################",
                            "###############################################",
                            "###############################################",
                            "###############################################",
                            "########DD###########################DD########",
                            "#######EK#############################KE#######",
                            "#######GH#############################HG#######",
                            "#######EK#############################KE#######",
                            "########DD###########################DD########",
                            "######################HHH######################",
                            "######################HJH######################",
                            "######################HHH######################",
                            "###############################################",
                            "###############################################",
                            "###############################################",
                            "###############################################",
                            "###############################################",
                            "###############################################",
                            "###############################################",
                            "###############################################",
                            "######################KLK######################",
                            "###############################################",
                            "###############################################",
                            "###############################################")
                    .aisle("####BBBBBBBBQRRHHHRRRVVLVVRRRHHHRRQBBBBBBBB####",
                            "####BBBBBBBB#SS###UUU#W#W#UUU###SS#BBBBBBBB####",
                            "####BBBIBBBB#######################BBBBIBBB####",
                            "###############################################",
                            "###############################################",
                            "###############################################",
                            "###############################################",
                            "###############################################",
                            "########N######X###############X######N########",
                            "######GK###############################KG######",
                            "#######H###############################H#######",
                            "######FK###############################KF######",
                            "########N#############################N########",
                            "######################HHH######################",
                            "######################HJH######################",
                            "######################HHH######################",
                            "###############################################",
                            "###############################################",
                            "###############################################",
                            "###############################################",
                            "###############################################",
                            "###############################################",
                            "###############################################",
                            "###############################################",
                            "######################KLK######################",
                            "###############################################",
                            "###############################################",
                            "###############################################")
                    .aisle("####BBBBBBBQIHHHRRVVVBBLBBVVVRRHHHIQBBBBBBB####",
                            "####BBBBBBB#Y###UU###ZZMZZ###UU###Y#BBBBBBB####",
                            "####BBBIBBB#########################BBBIBBB####",
                            "###############################################",
                            "###############################################",
                            "###############################################",
                            "###############################################",
                            "###############X###############X###############",
                            "########N#####XaX#############XaX#####N########",
                            "######EK#######X###############X#######KE######",
                            "######GH###############################HG######",
                            "######EK###############################KE######",
                            "########N#############################N########",
                            "######################HHH######################",
                            "######################HJH######################",
                            "######################HHH######################",
                            "###############################################",
                            "###############################################",
                            "###############################################",
                            "###############################################",
                            "###############################################",
                            "###############################################",
                            "###############################################",
                            "###############################################",
                            "###############################################",
                            "######################KLK######################",
                            "###############################################",
                            "###############################################")
                    .aisle("###BBBBBBBQRHIHRVVBBBHHLHHBBBVVRHIHRQBBBBBBB###",
                            "###BBBBBBB#b#c#U##ZZZdd#ddZZZ##U#c#e#BBBBBBB###",
                            "###BBBIBBB###########################BBBIBBB###",
                            "###############################################",
                            "###############################################",
                            "###############################################",
                            "###############X###############X###############",
                            "##############XXX#############XXX##############",
                            "#######N#####XXaXX###########XXaXX#####N#######",
                            "#####FK#######XaX#############XaX#######KF#####",
                            "######H########X###############X########H######",
                            "#####GK#################################KG#####",
                            "#######N###############################N#######",
                            "######################HHH######################",
                            "######################HJH######################",
                            "######################HHH######################",
                            "###############################################",
                            "###############################################",
                            "###############################################",
                            "###############################################",
                            "###############################################",
                            "###############################################",
                            "###############################################",
                            "###############################################",
                            "###############################################",
                            "######################KLK######################",
                            "###############################################",
                            "###############################################")
                    .aisle("###BBBBBBBQRHHIVBBHHHHHLHHHHHBBVIHHRQBBBBBBB###",
                            "###BBBBBBB#b##f#ZZddddd#dddddZZ#f##e#BBBBBBB###",
                            "###BBBIBBB###########################BBBIBBB###",
                            "###############################################",
                            "###############################################",
                            "###############X###############X###############",
                            "##############XX##############XXX##############",
                            "#############XXXXX###########XXXXX#############",
                            "#######N####XXXaXXX#########XXXaXXX####N#######",
                            "#####EK######XXaXX###########XXaXX######KE#####",
                            "#####GH#######XaX#############XaX#######HG#####",
                            "#####EK########X###############X########KE#####",
                            "#######N###############################N#######",
                            "######################HHH######################",
                            "######################HJH######################",
                            "######################HHH######################",
                            "###############################################",
                            "###############################################",
                            "###############################################",
                            "###############################################",
                            "###############################################",
                            "###############################################",
                            "###############################################",
                            "###############################################",
                            "###############################################",
                            "###############################################",
                            "######################KLK######################",
                            "###############################################")
                    .aisle("##BBBBBBBQRHHRVgLLLLLLLLLLLLLLLgVRHHRQBBBBBBB##",
                            "##BBBBBBB#b##h#aiiiiiiiOiiiiiiia#j##e#BBBBBBB##",
                            "##BBBIBBB######aM######k######Ma######BBBIBBB##",
                            "###############a###############a###############",
                            "###############a###############a###############",
                            "##############XaX#############XaX##############",
                            "#############XXaX############XXaXX#############",
                            "############XXXaXXX#########XXXaXXX############",
                            "######N####XaaaaaaaX#######XaaaaaaaX####N######",
                            "####GK######XaaaaaX#########XaaaaaX######KG####",
                            "#####H#######XaaaX###########XaaaX#######H#####",
                            "####FK########XaX#############XaX########KF####",
                            "######N########X###############X########N######",
                            "######################OOO######################",
                            "######################OJO######################",
                            "######################OOO######################",
                            "###############################################",
                            "###############################################",
                            "###############################################",
                            "###############################################",
                            "###############################################",
                            "###############################################",
                            "###############################################",
                            "###############################################",
                            "###############################################",
                            "###############################################",
                            "######################KLK######################",
                            "###############################################")
                    .aisle("##BBBBBBBQRHRVBLMMMMMMMLMMMMMMMLBVRHRQBBBBBBB##",
                            "##BBBBBBB#b#h#Zi###############iZ#j#e#BBBBBBB##",
                            "##BBBIBBB######M###############M######BBBIBBB##",
                            "###############################################",
                            "###############################################",
                            "###############X###############X###############",
                            "##############XXX#############XXX##############",
                            "#############XXXXX###########XXXXX#############",
                            "######N#####XXXaXXX#########XXXaXXX#####N######",
                            "####EK#######XXaXX###########XXaXX#######KE####",
                            "####GH########XaX#############XaX########HG####",
                            "####EK#########X###############X#########KE####",
                            "######N#################################N######",
                            "######################GGG######################",
                            "######################GGG######################",
                            "######################GGG######################",
                            "###############################################",
                            "###############################################",
                            "###############################################",
                            "###############################################",
                            "###############################################",
                            "###############################################",
                            "###############################################",
                            "###############################################",
                            "###############################################",
                            "###############################################",
                            "#######################N#######################",
                            "######################KLK######################")
                    .aisle("#BBBBBBBQRHHRVBLMllllMMLMMllllMLBVRHHRQBBBBBBB#",
                            "#BBBBBBB#b##h#Zi###############iZ#j##e#BBBBBBB#",
                            "#BBBIBBB###############################BBBIBBB#",
                            "###############################################",
                            "###############################################",
                            "###############################################",
                            "###############X###############X###############",
                            "##############XXX#############XXX##############",
                            "#####N#######XXaXX###########XXaXX#######N#####",
                            "###FK#########XaX#############XaX#########KF###",
                            "####H##########X######G########X##########H####",
                            "###GK################GGGG#################KG###",
                            "#####N##############GGGGG################N#####",
                            "####################GGGGG######################",
                            "######################GGG######################",
                            "######################GGG######################",
                            "###############################################",
                            "###############################################",
                            "###############################################",
                            "###############################################",
                            "###############################################",
                            "###############################################",
                            "###############################################",
                            "###############################################",
                            "###############################################",
                            "###############################################",
                            "#######################N#######################",
                            "######################KLK######################")
                    .aisle("#BBBBBBBQRHRVBZLMlllMMLPLMMlllMLHBVRHRQBBBBBBB#",
                            "#BBBBBBB#b#h#Zmi######X#X######inZ#j#e#BBBBBBB#",
                            "#BBBIBBB###############################BBBIBBB#",
                            "###############################################",
                            "###############################################",
                            "###############################################",
                            "###############################################",
                            "###############X###############X###############",
                            "#####N########XaX#############XaX########N#####",
                            "###EK##########X######G#G######X##########KE###",
                            "###GH###############GGGGG#################HG###",
                            "###EK###############GGGGGG################KE###",
                            "#####N#############GGGGGGGG##############N#####",
                            "###################GGGGGGG#####################",
                            "###################GG#GGGG#####################",
                            "#####################GGGGG#####################",
                            "###############################################",
                            "###############################################",
                            "###############################################",
                            "###############################################",
                            "###############################################",
                            "###############################################",
                            "###############################################",
                            "###############################################",
                            "###############################################",
                            "###############################################",
                            "#######################N#######################",
                            "######################KLK######################")
                    .aisle("#BBBBBBBQRHRVBHLMllMMLMMMLMMllMLHBVRHRQBBBBBBB#",
                            "#BBBBBBB#b#h#Zmi#####X###X#####inZ#j#e#BBBBBBB#",
                            "#BBBIBBB###############################BBBIBBB#",
                            "###############################################",
                            "###############################################",
                            "###############################################",
                            "###############################################",
                            "###############################################",
                            "#####N#########X###############X#########N#####",
                            "###GK###############G#GGGG################KG###",
                            "####H##############GGGGGGGG###############H####",
                            "###FK##############GGGGGGGG###############KF###",
                            "#####N###########GGGGGGGGGG##############N#####",
                            "##################G#GGGGGGGG###################",
                            "###################GGGGGGGGG###################",
                            "###################GGGGGGGGG###################",
                            "####################GGGGGG#G###################",
                            "###############################################",
                            "###############################################",
                            "###############################################",
                            "###############################################",
                            "###############################################",
                            "###############################################",
                            "###############################################",
                            "###############################################",
                            "###############################################",
                            "#######################N#######################",
                            "######################KLK######################")
                    .aisle("BBBBBBBQRHHRVBHLMlMMLIIIIILMMlMLHBVRHHRQBBBBBBB",
                            "BBBBBBB#b##h#Zmi####X#####X####inZ#j##e#BBBBBBB",
                            "BBBIBBB#############o#####o#############BBBIBBB",
                            "###############################################",
                            "###############################################",
                            "###############################################",
                            "###############################################",
                            "###############################################",
                            "####N#####################################N####",
                            "##EK###############GGGGG#G#################KE##",
                            "##GH###############GGGGGGGGGG##############HG##",
                            "##EK##############GGGGGGGGGGG##############KE##",
                            "####N############GGGGGGGGGGGG#############N####",
                            "#################GGGGGGGGGGGGG#################",
                            "#################GGGGGGGGG#GG##################",
                            "###################GGGGGGGGG###################",
                            "###################GGGGGGGGG###################",
                            "####################GGGGGGG####################",
                            "######################GG#######################",
                            "###############################################",
                            "###############################################",
                            "###############################################",
                            "###############################################",
                            "###############################################",
                            "###############################################",
                            "###############################################",
                            "#######################N#######################",
                            "######################KLK######################")
                    .aisle("BBBBBBBQRHRVBHHLMMMLIVVVVVILMMMLHHBVRHRQBBBBBBB",
                            "BBBBBBB#b#h#Zmmi###X#######X###innZ#j#e#BBBBBBB",
                            "BBBIBBB#################################BBBIBBB",
                            "###############################################",
                            "###############################################",
                            "###############################################",
                            "###############################################",
                            "###############################################",
                            "####N#################GGGG################N####",
                            "##FK###############GGGGGGG#################KF##",
                            "###H##############GGGGGGGGGGG##############H###",
                            "##GK#############GGGGGGGGGGGGG#############KG##",
                            "####N###########GGGGGGGGGGGGG#############N####",
                            "#################GGGGGGGGGGGGGG################",
                            "#################GGGGGGGGGGGGGG################",
                            "#################GGGGGGGGGG####################",
                            "##################GGGGGGGG#####################",
                            "##################GGGGGGGG#####################",
                            "######################GGG######################",
                            "###############################################",
                            "###############################################",
                            "###############################################",
                            "###############################################",
                            "###############################################",
                            "###############################################",
                            "###############################################",
                            "#######################N#######################",
                            "######################KLK######################")
                    .aisle("BBBBBBBQRHRVBHHLMMLMIVVVVVIMLMMLHHBVRHRQBBBBBBB",
                            "BBBBBBB#b#hWZmmi##X###VVV###X##innZWj#e#BBBBBBB",
                            "BBBBBBB###############VVV###############BBBBBBB",
                            "##CCC#################VVV#################CCC##",
                            "######################VVV######################",
                            "######################VVV######################",
                            "######################VVV######################",
                            "######################VVV######################",
                            "##DDN################GVVVG################NDD##",
                            "##EK###############GGGVVVGGG###############KE##",
                            "##GH#############GGGGGVVV#GG###############HG##",
                            "##EK############GGGGGGVVVGGGGG#############KE##",
                            "##DKN############GG##GVVVGGGGGG###########NKD##",
                            "####OHHHHHHHHHHOGGGGGGGGGGGGGGGOHHHHHHHHHHO####",
                            "####OHHHHHHHHHHOGGGGGGGGGGGGG#GOHHHHHHHHHHO####",
                            "####OHHHHHHHHHHOGGGGGGGGGGGG#GGOHHHHHHHHHHO####",
                            "#####K############GGGGGGGGGGG############K#####",
                            "#####K############GGGGGGGGG##############K#####",
                            "######K##############GGGG###############K######",
                            "######K###############OOO###############K######",
                            "#######K##############HHH##############K#######",
                            "#######K##############HHH##############K#######",
                            "########K#############HHH#############K########",
                            "#########K############HHH############K#########",
                            "##########KK##########HHH##########KK##########",
                            "############KK########HHH########KK############",
                            "##############KK######MMM######KK##############",
                            "################KKKKKKKLKKKKKKK################")
                    .aisle("BBBBBBBLLLLLLLLLLLPMIVVVVVIMPLLLLLLLLLLLBBBBBBB",
                            "BBBBBBBL####M##O######VVV######O#######LBBBBBBB",
                            "BBBBBBBL#######k######VVV######k#######LBBBBBBB",
                            "##CJMNNN##############VVV##############NNNMJC##",
                            "###J##################VVV##################J###",
                            "###J##################VVV##################J###",
                            "###J##################VVV##################J###",
                            "###J##################VVV##################J###",
                            "##DJN################GVVVG################NJD##",
                            "##GJ################G#VVVGGG###############JG##",
                            "##HJ#############GGGGGVVVGGGG##############JH##",
                            "##FJ#############GGGGGVVVGGGGG#############JF##",
                            "##DLN###########GGG#GGVVV#GGGGG###########NLD##",
                            "####LHHHHHHHHHHOGGGGGGGGGGGGGGGOHHHHHHHHHHL####",
                            "####PJJJJJJJJJJJGGGGGGGGGGGGGGGJJJJJJJJJJJP####",
                            "####LHHHHHHHHHHOGGGGGGGGGGGGGGGOHHHHHHHHHHL####",
                            "#####L###########GGGGGGGGGGG#############L#####",
                            "#####L##############GGGGGGGG#############L#####",
                            "######L##############GGGGG##############L######",
                            "######L###############OJO###############L######",
                            "#######L##############HJH##############L#######",
                            "#######L##############HJH##############L#######",
                            "########L#############HJH#############L########",
                            "#########L############HJH############L#########",
                            "##########LL##########HJH##########LL##########",
                            "############LL########HJH########LL############",
                            "##############LLNNNNNNMJMNNNNNNLL##############",
                            "################LLLLLLLPLLLLLLL################")
                    .aisle("BBBBBBBQRHRVBHHLMMLMIVVVVVIMLMMLHHBVRHRQBBBBBBB",
                            "BBBBBBB###hWZmmi##X###VVV###X##innZWj#e#BBBBBBB",
                            "BBBBBBB###############VVV###############BBBBBBB",
                            "##CCC#################VVV#################CCC##",
                            "######################VVV######################",
                            "######################VVV######################",
                            "######################VVV######################",
                            "######################VVV######################",
                            "##DDN##############GGGVVVG################NDD##",
                            "##EK###############GGGVVVGGG###############KE##",
                            "##GH############GGGGGGVVVGGGG##############HG##",
                            "##EK#############GGGGGVVVGGGGG#############KE##",
                            "##DKN############GGGGGVVV#GGGGG###########NKD##",
                            "####OHHHHHHHHHHOGGGGGGGGGGGGGGGOHHHHHHHHHHO####",
                            "####OHHHHHHHHHHOGGGGGGGGG#GGGGGOHHHHHHHHHHO####",
                            "####OHHHHHHHHHHOGGGGGGGGGGGG#GGOHHHHHHHHHHO####",
                            "#####K############GGGGGGGGGGGG###########K#####",
                            "#####K############GGGGGGGGGG#############K#####",
                            "######K#############GGGGGG##############K######",
                            "######K###############OOO###############K######",
                            "#######K###############HH##############K#######",
                            "#######K###############HH##############K#######",
                            "########K##############HH#############K########",
                            "#########K#############HH############K#########",
                            "##########KK###########HH##########KK##########",
                            "############KK#########HH########KK############",
                            "##############KK######MMM######KK##############",
                            "################KKKKKKKLKKKKKKK################")
                    .aisle("BBBBBBBQRHRVBHHLMMMLIVVVVVILMMMLHHBVRHRQBBBBBBB",
                            "BBBBBBB#b#h#Zmmi###X#######X###innZ#j#e#BBBBBBB",
                            "BBBIBBB#################################BBBIBBB",
                            "###############################################",
                            "###############################################",
                            "###############################################",
                            "###############################################",
                            "###############################################",
                            "####N##############G#GGGGG################N####",
                            "##FK################GG#GGG#################KF##",
                            "###H#############GGGGGGGGGGGG##############H###",
                            "##GK#############GGGG#GGGGGGGG#############KG##",
                            "####N###########GGGGGGGGGGGGGG############N####",
                            "################GGGGGGGGGGGGGGG################",
                            "################GGGGGGGGGG#GGGG################",
                            "##################GGGGGGGGGGGG#################",
                            "##################GGGGGGGGGG###################",
                            "###################GGGGGGGG####################",
                            "##########################G####################",
                            "###############################################",
                            "###############################################",
                            "###############################################",
                            "###############################################",
                            "###############################################",
                            "###############################################",
                            "###############################################",
                            "#######################N#######################",
                            "######################KLK######################")
                    .aisle("BBBBBBBQRHHRVBHLMlMMLIIIIILMMlMLHBVRHHRQBBBBBBB",
                            "BBBBBBB#b##h#Zmi####X#####X####inZ#j##e#BBBBBBB",
                            "BBBIBBB#############o#####o#############BBBIBBB",
                            "###############################################",
                            "###############################################",
                            "###############################################",
                            "###############################################",
                            "###############################################",
                            "####N#################GGGG################N####",
                            "##EK##################GGGGG################KE##",
                            "##GH##############GG#GGGGGGG###############HG##",
                            "##EK##############GGGGG#GGGGGG#############KE##",
                            "####N############GGGGGGGGGGGGG############N####",
                            "#################GGGGG#GGGGGGGG################",
                            "#################GGGG#GGGGGGGG#################",
                            "##################GGGGGGGGGGG##################",
                            "###################GGGGGGGGGG##################",
                            "#####################GGGGG#####################",
                            "#######################G#G#####################",
                            "###############################################",
                            "###############################################",
                            "###############################################",
                            "###############################################",
                            "###############################################",
                            "###############################################",
                            "###############################################",
                            "#######################N#######################",
                            "######################KLK######################")
                    .aisle("#BBBBBBBQRHRVBHLMllMMLMMMLMMllMLHBVRHRQBBBBBBB#",
                            "#BBBBBBB#b#h#Zmi#####X###X#####inZ#j#e#BBBBBBB#",
                            "#BBBIBBB###############################BBBIBBB#",
                            "###############################################",
                            "###############################################",
                            "###############################################",
                            "###############################################",
                            "###############################################",
                            "#####N#########X########G######X#########N#####",
                            "###GK#################GGG#################KG###",
                            "####H##############G##GGGGG###############H####",
                            "###FK##############GGGGGGGGGG#############KF###",
                            "#####N############GGGGGGGGGGG############N#####",
                            "##################GGGGGGGGGGG#G################",
                            "##################GGG#GGGGGGGG#################",
                            "###################GGGGGGGG##G#################",
                            "#####################G#GGGG####################",
                            "#####################G#G#G#####################",
                            "#######################G#######################",
                            "###############################################",
                            "###############################################",
                            "###############################################",
                            "###############################################",
                            "###############################################",
                            "###############################################",
                            "###############################################",
                            "#######################N#######################",
                            "######################KLK######################")
                    .aisle("#BBBBBBBQRHRVBHLMlllMMLPLMMlllMLHBVRHRQBBBBBBB#",
                            "#BBBBBBB#b#h#Zmi######X#X######inZ#j#e#BBBBBBB#",
                            "#BBBIBBB###############################BBBIBBB#",
                            "###############################################",
                            "###############################################",
                            "###############################################",
                            "###############################################",
                            "###############X###############X###############",
                            "#####N########XaX#############XaX########N#####",
                            "###EK##########X###############X##########KE###",
                            "###GH####################G################HG###",
                            "###EK##############GGGGGGGG###############KE###",
                            "#####N#############GGGGGGGGG#############N#####",
                            "###################GGGGGGGGG###################",
                            "###################GGGGGGGGG###################",
                            "####################GGGGGG#####################",
                            "#######################GG######################",
                            "###############################################",
                            "###############################################",
                            "###############################################",
                            "###############################################",
                            "###############################################",
                            "###############################################",
                            "###############################################",
                            "###############################################",
                            "###############################################",
                            "#######################N#######################",
                            "######################KLK######################")
                    .aisle("#BBBBBBBQRHHRVBLMllllMMLMMllllMLBVRHHRQBBBBBBB#",
                            "#BBBBBBB#b##h#Zi###############iZ#j##e#BBBBBBB#",
                            "#BBBIBBB###############################BBBIBBB#",
                            "###############################################",
                            "###############################################",
                            "###############################################",
                            "###############X###############X###############",
                            "##############XX##############XXX##############",
                            "#####N#######XXaX############XXaXX#######N#####",
                            "###FK#########XaX#############XaX#########KF###",
                            "####H##########X###############X##########H####",
                            "###GK##################G#G################KG###",
                            "#####N###############GGGGGG##############N#####",
                            "####################GGGGGGG####################",
                            "###################GGGGGGGG####################",
                            "######################G#GG#####################",
                            "########################G######################",
                            "###############################################",
                            "###############################################",
                            "###############################################",
                            "###############################################",
                            "###############################################",
                            "###############################################",
                            "###############################################",
                            "###############################################",
                            "###############################################",
                            "#######################N#######################",
                            "######################KLK######################")
                    .aisle("##BBBBBBBQRHRVBLMMMMMMMLMMMMMMMLBVRHRQBBBBBBB##",
                            "##BBBBBBB#b#h#Zi###############iZ#j#e#BBBBBBB##",
                            "##BBBIBBB######M###############M######BBBIBBB##",
                            "###############################################",
                            "###############################################",
                            "###############X###############X###############",
                            "##############XX##############XXX##############",
                            "#############XXX#############XXXXX#############",
                            "######N#####XXXaX###########XXXaXXX#####N######",
                            "####EK#######XXaX############XXaXX#######KE####",
                            "####GH########XaX#############XaX########HG####",
                            "####EK#########X###############X#########KE####",
                            "######N###############GGG###############N######",
                            "#####################GGGG######################",
                            "######################GGG######################",
                            "######################GGG######################",
                            "###############################################",
                            "###############################################",
                            "###############################################",
                            "###############################################",
                            "###############################################",
                            "###############################################",
                            "###############################################",
                            "###############################################",
                            "###############################################",
                            "###############################################",
                            "#######################N#######################",
                            "######################KLK######################")
                    .aisle("##BBBBBBBQRHHRVgLLLLLLLLLLLLLLLgVRHHRQBBBBBBB##",
                            "##BBBBBBB#b##h#aiiiiiiiOiiiiiiia#j##e#BBBBBBB##",
                            "##BBBIBBB######aM######k######Ma######BBBIBBB##",
                            "###############a###############a###############",
                            "###############a###############a###############",
                            "##############XaX#############XaX##############",
                            "#############XXaXX###########XXaXX#############",
                            "############XXXaXXX#########XXXaXXX############",
                            "######N####XaaaaaaaX#######XaaaaaaaX####N######",
                            "####GK######XaaaaaX#########XaaaaaX######KG####",
                            "#####H#######XaaaX###########XaaaX#######H#####",
                            "####FK########XaX#############XaX########KF####",
                            "######N########X###############X########N######",
                            "######################OOO######################",
                            "######################OJO######################",
                            "######################OOO######################",
                            "###############################################",
                            "###############################################",
                            "###############################################",
                            "###############################################",
                            "###############################################",
                            "###############################################",
                            "###############################################",
                            "###############################################",
                            "###############################################",
                            "###############################################",
                            "######################KLK######################",
                            "###############################################")
                    .aisle("###BBBBBBBQRHHIVBBHHHHHLHHHHHBBVIHHRQBBBBBBB###",
                            "###BBBBBBB#b##f#ZZppppp#pppppZZ#f##e#BBBBBBB###",
                            "###BBBIBBB###########################BBBIBBB###",
                            "###############################################",
                            "###############################################",
                            "###############X###############X###############",
                            "##############XXX#############XXX##############",
                            "#############XXXXX###########XXXXX#############",
                            "#######N####XXXaXXX#########XXXaXXX####N#######",
                            "#####EK######XXaXX###########XXaXX######KE#####",
                            "#####GH#######XaX#############XaX#######HG#####",
                            "#####EK########X###############X########KE#####",
                            "#######N###############################N#######",
                            "######################HHH######################",
                            "######################HJH######################",
                            "######################HHH######################",
                            "###############################################",
                            "###############################################",
                            "###############################################",
                            "###############################################",
                            "###############################################",
                            "###############################################",
                            "###############################################",
                            "###############################################",
                            "###############################################",
                            "###############################################",
                            "######################KLK######################",
                            "###############################################")
                    .aisle("###BBBBBBBQRHIHRVVBBBHHLHHBBBVVRHIHRQBBBBBBB###",
                            "###BBBBBBB#b#c#q##ZZZpp#ppZZZ##q#c#e#BBBBBBB###",
                            "###BBBIBBB###########################BBBIBBB###",
                            "###############################################",
                            "###############################################",
                            "###############################################",
                            "###############X###############X###############",
                            "##############XXX#############XXX##############",
                            "#######N#####XXaXX###########XXaXX#####N#######",
                            "#####FK#######XaX#############XaX#######KF#####",
                            "######H########X###############X########H######",
                            "#####GK#################################KG#####",
                            "#######N###############################N#######",
                            "######################HHH######################",
                            "######################HJH######################",
                            "######################HHH######################",
                            "###############################################",
                            "###############################################",
                            "###############################################",
                            "###############################################",
                            "###############################################",
                            "###############################################",
                            "###############################################",
                            "###############################################",
                            "###############################################",
                            "######################KLK######################",
                            "###############################################",
                            "###############################################")
                    .aisle("####BBBBBBBQIHHHRRVVVBBLBBVVVRRHHHIQBBBBBBB####",
                            "####BBBBBBB#Y###qq###ZZ#ZZ###qq###Y#BBBBBBB####",
                            "####BBBIBBB#########################BBBIBBB####",
                            "###############################################",
                            "###############################################",
                            "###############################################",
                            "###############################################",
                            "###############X###############X###############",
                            "########N#####XaX#############XaX#####N########",
                            "######EK#######X###############X#######KE######",
                            "######GH###############################HG######",
                            "######EK###############################KE######",
                            "########N#############################N########",
                            "######################HHH######################",
                            "######################HJH######################",
                            "######################HHH######################",
                            "###############################################",
                            "###############################################",
                            "###############################################",
                            "###############################################",
                            "###############################################",
                            "###############################################",
                            "###############################################",
                            "###############################################",
                            "###############################################",
                            "######################KLK######################",
                            "###############################################",
                            "###############################################")
                    .aisle("####BBBBBBBBQRRHHHRRRVVLVVRRRHHHRRQBBBBBBBB####",
                            "####BBBBBBBB#rr###qqq#W#W#qqq###rr#BBBBBBBB####",
                            "####BBBIBBBB#######################BBBBIBBB####",
                            "###############################################",
                            "###############################################",
                            "###############################################",
                            "###############################################",
                            "###############################################",
                            "########N######X###############X######N########",
                            "######GK###############################KG######",
                            "#######H###############################H#######",
                            "######FK###############################KF######",
                            "########N#############################N########",
                            "######################HHH######################",
                            "######################HJH######################",
                            "######################HHH######################",
                            "###############################################",
                            "###############################################",
                            "###############################################",
                            "###############################################",
                            "###############################################",
                            "###############################################",
                            "###############################################",
                            "###############################################",
                            "######################KLK######################",
                            "###############################################",
                            "###############################################",
                            "###############################################")
                    .aisle("#####BBBBBBBBQQRRHHHHRRLRRHHHHRRQQBBBBBBBB#####",
                            "#####BBBBBBBB##rr####qq#qq####rr##BBBBBBBB#####",
                            "#####BBBBBBBB#####################BBBBBBBB#####",
                            "########CCD#########################DCC########",
                            "###############################################",
                            "###############################################",
                            "###############################################",
                            "###############################################",
                            "########DD###########################DD########",
                            "#######EK#############################KE#######",
                            "#######GH#############################HG#######",
                            "#######EK#############################KE#######",
                            "########DD###########################DD########",
                            "######################HHH######################",
                            "######################HJH######################",
                            "######################HHH######################",
                            "###############################################",
                            "###############################################",
                            "###############################################",
                            "###############################################",
                            "###############################################",
                            "###############################################",
                            "###############################################",
                            "###############################################",
                            "######################KLK######################",
                            "###############################################",
                            "###############################################",
                            "###############################################")
                    .aisle("#####BBBBBBBBBBQQRRRHHHLHHHRRRQQBBBBBBBBBB#####",
                            "#####BBBBBBBBBB##rrr#######rrr##BBBBBBBBBB#####",
                            "#####BBBBBBBBBB#################BBBBBBBBBB#####",
                            "########CTC#########################CTC########",
                            "#########T###########################T#########",
                            "#########T###########################T#########",
                            "#########T###########################T#########",
                            "#########T###########################T#########",
                            "########DTD#########################DTD########",
                            "########HT###########################TH########",
                            "########GT###########################TG########",
                            "########HT###########################TH########",
                            "########DDD#########################DDD########",
                            "######################HHH######################",
                            "######################HJH######################",
                            "######################HHH######################",
                            "###############################################",
                            "###############################################",
                            "###############################################",
                            "###############################################",
                            "###############################################",
                            "###############################################",
                            "###############################################",
                            "######################KLK######################",
                            "###############################################",
                            "###############################################",
                            "###############################################",
                            "###############################################")
                    .aisle("######BBBBBBBBBBBQQQRRRLRRRQQQBBBBBBBBBBB######",
                            "######BBBBBBBBBBB###rrr#rrr###BBBBBBBBBBB######",
                            "######BBBBBBBBBBB#############BBBBBBBBBBB######",
                            "########DCC#########################CCD########",
                            "###############################################",
                            "###############################################",
                            "###############################################",
                            "###############################################",
                            "#########DDNN#####################NNDD#########",
                            "#########HK#########################KH#########",
                            "#########GH#########################HG#########",
                            "#########HK#########################KH#########",
                            "#########DDNN#####################NNDD#########",
                            "######################HHH######################",
                            "######################HJH######################",
                            "######################HHH######################",
                            "###############################################",
                            "###############################################",
                            "###############################################",
                            "###############################################",
                            "###############################################",
                            "###############################################",
                            "######################KLK######################",
                            "###############################################",
                            "###############################################",
                            "###############################################",
                            "###############################################",
                            "###############################################")
                    .aisle("#######BBBBBBBBBBBBBQQQLQQQBBBBBBBBBBBBB#######",
                            "#######BBBBBBBBBBBBB###L###BBBBBBBBBBBBB#######",
                            "#######BBBBIIBBBBBBB###L###BBBBBBBIIBBBB#######",
                            "#######################N#######################",
                            "###############################################",
                            "###############################################",
                            "###############################################",
                            "###############################################",
                            "#############NN#################NN#############",
                            "##########EKK#####################KKE##########",
                            "##########GHH#####################HHG##########",
                            "##########EKK#####################KKE##########",
                            "#############NN#################NN#############",
                            "######################HHH######################",
                            "######################HJH######################",
                            "######################HHH######################",
                            "###############################################",
                            "###############################################",
                            "###############################################",
                            "###############################################",
                            "######################KLK######################",
                            "######################KLK######################",
                            "###############################################",
                            "###############################################",
                            "###############################################",
                            "###############################################",
                            "###############################################",
                            "###############################################")
                    .aisle("########BBBBBBBBBBBBBBBBBBBBBBBBBBBBBBB########",
                            "########BBBBBBBBBBBBBBBBBBBBBBBBBBBBBBB########",
                            "########BBBBBIIBBBBBBBBBBBBBBBBBIIBBBBB########",
                            "#######################N#######################",
                            "###############################################",
                            "###############################################",
                            "###############################################",
                            "###############################################",
                            "###############NN#############NN###############",
                            "###########GEKK#################KKEG###########",
                            "############GHH#################HHG############",
                            "###########FEKK#################KKEF###########",
                            "###############NN#############NN###############",
                            "######################HHH######################",
                            "######################HJH######################",
                            "######################HHH######################",
                            "###############################################",
                            "###############################################",
                            "######################KLK######################",
                            "######################KLK######################",
                            "###############################################",
                            "###############################################",
                            "###############################################",
                            "###############################################",
                            "###############################################",
                            "###############################################",
                            "###############################################",
                            "###############################################")
                    .aisle("#########BBBBBBBBBBBBBBBBBBBBBBBBBBBBB#########",
                            "#########BBBBBBBBBBBBBBBBBBBBBBBBBBBBB#########",
                            "#########BBBBBBIIBBBBBBBBBBBBBIIBBBBBB#########",
                            "#######################N#######################",
                            "###############################################",
                            "###############################################",
                            "###############################################",
                            "###############################################",
                            "#################NNN#######NNN#################",
                            "#############FEKK#############KKEF#############",
                            "##############GHH#############HHG##############",
                            "#############GEKK#############KKEG#############",
                            "#################NNN#######NNN#################",
                            "######################HHH######################",
                            "######################HJH######################",
                            "######################HHH######################",
                            "######################KLK######################",
                            "######################KLK######################",
                            "###############################################",
                            "###############################################",
                            "###############################################",
                            "###############################################",
                            "###############################################",
                            "###############################################",
                            "###############################################",
                            "###############################################",
                            "###############################################",
                            "###############################################")
                    .aisle("###########BBBBBBBBBBBBBBBBBBBBBBBBB###########",
                            "###########BBBBBBBBBBBBBBBBBBBBBBBBB###########",
                            "###########BBBBBBIIIBBBBBBBIIIBBBBBB###########",
                            "######################CMC######################",
                            "###############################################",
                            "###############################################",
                            "###############################################",
                            "###############################################",
                            "####################NNNNNNN####################",
                            "###############GEKKK#######KKKEG###############",
                            "################GHHH#######HHHG################",
                            "###############FEKKK#######KKKEF###############",
                            "####################NNNNNNN####################",
                            "######################OLO######################",
                            "######################OPO######################",
                            "######################OLO######################",
                            "###############################################",
                            "###############################################",
                            "###############################################",
                            "###############################################",
                            "###############################################",
                            "###############################################",
                            "###############################################",
                            "###############################################",
                            "###############################################",
                            "###############################################",
                            "###############################################",
                            "###############################################")
                    .aisle("#############BBBBBBBBBBBBBBBBBBBBB#############",
                            "#############BBBBBBBBBBBBBBBBBBBBB#############",
                            "#############BBBBBBBIIBBBIIBBBBBBB#############",
                            "######################CJC######################",
                            "#######################J#######################",
                            "#######################J#######################",
                            "#######################J#######################",
                            "#######################J#######################",
                            "######################DJD######################",
                            "#################FEGKKKJKKKGEF#################",
                            "##################G#HHHJHHH#G##################",
                            "#################GEFKKKJKKKFEG#################",
                            "######################KLK######################",
                            "###############################################",
                            "###############################################",
                            "###############################################",
                            "###############################################",
                            "###############################################",
                            "###############################################",
                            "###############################################",
                            "###############################################",
                            "###############################################",
                            "###############################################",
                            "###############################################",
                            "###############################################",
