package com.moguang.ctnhmana.registry;

import com.gregtechceu.gtceu.GTCEu;
import com.gregtechceu.gtceu.api.data.RotationState;
import com.gregtechceu.gtceu.api.machine.MultiblockMachineDefinition;
import com.gregtechceu.gtceu.api.machine.multiblock.PartAbility;
import com.gregtechceu.gtceu.api.machine.property.GTMachineModelProperties;
import com.gregtechceu.gtceu.api.machine.trait.RecipeLogic;
import com.gregtechceu.gtceu.api.pattern.BlockPattern;
import com.gregtechceu.gtceu.api.pattern.FactoryBlockPattern;
import com.gregtechceu.gtceu.api.pattern.MultiblockShapeInfo;
import com.gregtechceu.gtceu.api.pattern.Predicates;
import com.gregtechceu.gtceu.api.recipe.OverclockingLogic;
import com.gregtechceu.gtceu.common.data.GTRecipeModifiers;
import com.gregtechceu.gtceu.common.data.GTRecipeTypes;
import com.gregtechceu.gtceu.utils.GTUtil;

import net.minecraft.core.Direction;
import net.minecraft.network.chat.Component;
import net.minecraft.resources.ResourceLocation;
import net.minecraft.world.item.DyeColor;
import net.minecraft.world.level.block.Blocks;
import net.minecraftforge.registries.ForgeRegistries;

import com.moguang.ctnhmana.CTNHMana;
import com.moguang.ctnhmana.Mutiblock.*;
import com.moguang.ctnhmana.Mutiblock.parts.CMPartsAbility;
import com.moguang.ctnhmana.api.pattern.CMPredicates;
import com.moguang.ctnhmana.client.render.ZenithMatrixBlockEntityRender;
import com.moguang.ctnhmana.registry.multiblock.Botania;
import com.moguang.ctnhmana.registry.multiblock.ManaMachine;
import com.moguang.ctnhmana.registry.multiblock.misc;
import tech.vixhentx.mcmod.ctnhlib.langprovider.Lang;
import vazkii.botania.common.block.BotaniaBlocks;
import wayoftime.bloodmagic.common.block.BloodMagicBlocks;
import wayoftime.bloodmagic.common.fluid.BloodMagicFluids;

import java.util.ArrayList;
import java.util.List;

import static com.github.L_Ender.cataclysm.init.ModBlocks.*;
import static com.gregtechceu.gtceu.api.pattern.Predicates.abilities;
import static com.gregtechceu.gtceu.common.data.GTBlocks.*;
import static com.gregtechceu.gtceu.common.data.models.GTMachineModels.createWorkableCasingMachineModel;
import static com.moguang.ctnhmana.CTNHMana.REGISTRATE;
import static com.moguang.ctnhmana.Mutiblock.HellForgeMachine.hellforgeLang;
import static com.moguang.ctnhmana.Mutiblock.ManaForceTransformer.MFT_Lang;
import static com.moguang.ctnhmana.Mutiblock.MysticSpire.spireTooltipsLang;
import static com.moguang.ctnhmana.data.lang.ChineseLangHandler.*;
import static com.moguang.ctnhmana.registry.CMBlocks.*;
import static com.moguang.ctnhmana.utils.ModUtils.BloodMagicRL;
import static com.moguang.ctnhmana.utils.ModUtils.BotaniaRL;
import static net.minecraft.world.level.block.Blocks.*;
import static wayoftime.bloodmagic.common.block.BloodMagicBlocks.*;

@SuppressWarnings("removal")
public class CMMultiblockMachines {

    static {
        REGISTRATE.creativeModeTab(() -> CMCreativeModeTabs.MACHINE);
    }

    public static void init() {
        com.moguang.ctnhmana.registry.multiblock.BloodMagic.init();
        Botania.init();
        misc.init();
        ManaMachine.init();
        // ZenithMachine.init();
    }

    public static List<Component> addManaMachineTooltips(Lang[] langs, int consumption) {
        List<Component> list = new ArrayList<>();
        int y = 0;
        for (Lang lang : langs) {
            if (y != 3) list.add(lang.translate());
            if (y == 3) list.add(lang.translate(consumption));
            y += 1;
        }
        return list;
    }

    // 不需要这个，lib自带
    // public static List<Component> addMachineTooltips(Lang[] langs)
    // {
    // List<Component> list=new ArrayList<>();
    // int y=0;
    // for(Lang lang:langs)
    // {
    // list.add(lang.translate());
    // }
    // return list;
    // }

    public final static MultiblockMachineDefinition MANA_REACTOR = REGISTRATE
            .multiblock("mana_reactor", holder -> new ManaReactor(holder, 4))
            .cnLangValue("§b魔力反应器")
            .tooltips(addManaMachineTooltips(basemanamutiblockLang, 4))
            .appearanceBlock(() -> BotaniaBlocks.livingrockPolished)
            .rotationState(RotationState.NON_Y_AXIS)
            .recipeType(CMRecipeTypes.MANA_REACTOR_RECIPES)
            .recipeModifiers(ManaReactor::recipeModifier,
                    GTRecipeModifiers.ELECTRIC_OVERCLOCK.apply(OverclockingLogic.NON_PERFECT_OVERCLOCK_SUBTICK))
            .pattern(definition -> FactoryBlockPattern.start()
                    .aisle("AAAAAAAAAAAAAAAAA", "###BB#######BB###", "#################", "#################",
                            "#################", "#################", "#################", "#################",
                            "#################", "#################", "#################", "#################",
                            "#################", "#################", "#################", "#################",
                            "#################")
                    .aisle("AAAAAAAAAAAAAAAAA", "##BAAC#####CAAB##", "#####C#####C#####", "#####CCDDDCC#####",
                            "######C###C######", "#################", "#################", "#################",
                            "#######EEE#######", "#######EEE#######", "#######EEE#######", "#################",
                            "#################", "#################", "#################", "#################",
                            "#################")
                    .aisle("AAAAAAAAAAAAAAAAA", "#BAA#########AAB#", "###BA#######AB###", "#####DD###DD#####",
                            "#######DDD#######", "#################", "######FFFFF######", "#####EEEEEEE#####",
                            "#####EE###EE#####", "#####EE###EE#####", "#####EE###EE#####", "#####EEEEEEE#####",
                            "######EEEEE######", "#################", "#################", "#################",
                            "#################")
                    .aisle("AAAAAAAAAAAAAAAAA", "BAA###########AAB", "##BA#########AB##", "####D#######D####",
                            "#####DDFFFDD#####", "#####FFFFFFF#####", "####FFF####FF####", "####E#######E####",
                            "###EE#######EE###", "###EE#######EE###", "###EE#######EE###", "####E#######E####",
                            "####EE#####EE####", "#####GGGGGGG#####", "#######GGG#######", "#################",
                            "#################")
                    .aisle("AAAAAAAAAAAAAAAAA", "BA#############AB", "##A###########A##", "###D#########D###",
                            "####DFFFFFFFD####", "####F#######F####", "###F#########F###", "###E#########E###",
                            "###E#########E###", "###E#########E###", "###E#########E###", "###E#########E###",
                            "###E#########E###", "####G#######G####", "#####GGGGGGG#####", "#################",
                            "#################")
                    .aisle("AAAAAAAAAAAAAAAAA", "#C#############C#", "#C#############C#", "#CD##FFFFFF###DC#",
                            "###DFF#####FFD###", "###F#########F###", "###F#########F###", "##E###########E##",
                            "##E###########E##", "##E###########E##", "##E###########E##", "##E###########E##",
                            "###E#########E###", "###G#########G###", "####GG#####GG####", "######GGGGG######",
                            "#################")
                    .aisle("AAAAAAAAAAAAAAAAA", "#################", "#################", "#CD##FFFFFFF##DC#",
                            "#C#DF#######FD#C#", "###F#########F###", "##F###########F##", "##E###########E##",
                            "##E###########E##", "##E###########E##", "##E###########E##", "##E###########E##",
                            "##E###########E##", "###G#########G###", "####G#######G####", "#####GGGGGGG#####",
                            "#################")
                    .aisle("AAAAAAAAAAAAAAAAA", "#################", "#######FFF#######", "#D###FF###FF###D#",
                            "##DFF#######FFD##", "###F#########F###", "##F###########F##", "##E###########E##",
                            "#E#############E#", "#E#############E#", "#E#############E#", "##E###########E##",
                            "##E###########E##", "###G#########G###", "###GG#######GG###", "#####GG###GG#####",
                            "#######GGG#######")
                    .aisle("AAAAAAAAAAAAAAAAA", "#################", "#######FFF#######", "#D###FF###FF###D#",
                            "##DFF#######FFD##", "###F#########F###", "##F###########F##", "##E###########E##",
                            "#E#############E#", "#E#############E#", "#E#############E#", "##E###########E##",
                            "##E###########E##", "###G#########G###", "###GG#######GG###", "#####GG###GG#####",
                            "#######GGG#######")
                    .aisle("AAAAAAAAAAAAAAAAA", "#################", "#######FFF#######", "#D###FF###FF###D#",
                            "##DFF#######FFD##", "###F#########F###", "##F###########F##", "##E###########E##",
                            "#E#############E#", "#E#############E#", "#E#############E#", "##E###########E##",
                            "##E###########E##", "###G#########G###", "###GG#######GG###", "#####GG###GG#####",
                            "#######GGG#######")
                    .aisle("AAAAAAAAAAAAAAAAA", "#################", "#################", "#CD##FFFFFFF##DC#",
                            "#C#DF#######FD#C#", "###F#########F###", "##F###########F##", "##E###########E##",
                            "##E###########E##", "##E###########E##", "##E###########E##", "##E###########E##",
                            "##E###########E##", "###G#########G###", "####G#######G####", "#####GGGGGGG#####",
                            "#################")
                    .aisle("AAAAAAAAAAAAAAAAA", "#C#############C#", "#C#############C#", "#CD###FFFFF###DC#",
                            "###DFF#####FFD###", "###F#########F###", "###F#########F###", "##E###########E##",
                            "##E###########E##", "##E###########E##", "##E###########E##", "##E###########E##",
                            "###E#########E###", "###G#########G###", "####GG#####GG####", "######GGGGG######",
                            "#################")
                    .aisle("AAAAAAAAAAAAAAAAA", "BA#############AB", "##A###########A##", "###D#########D###",
                            "####DFFFFFFFD####", "####F#######F####", "###F#########F###", "###E#########E###",
                            "###E#########E###", "###E#########E###", "###E#########E###", "###E#########E###",
                            "###E#########E###", "####G#######G####", "#####GGGGGGG#####", "#################",
                            "#################")
                    .aisle("AAAAAAAAAAAAAAAAA", "BAA###########AAB", "##BA#########AB##", "####D#######D####",
                            "#####DDFFFDD#####", "#####FFFFFFF#####", "####FF#####FF####", "####E#######E####",
                            "###EE#######EE###", "###EE#######EE###", "###EE#######EE###", "####E#######E####",
                            "####EE#####EE####", "#####GGGGGGG#####", "#######GGG#######", "#################",
                            "#################")
                    .aisle("AAAAAAAAAAAAAAAAA", "#BAA#########AAB#", "###BA#######AB###", "#####DD###DD#####",
                            "#######DDD#######", "#################", "######FFFFF######", "#####EEEEEEE#####",
                            "#####EE###EE#####", "#####EE###EE#####", "#####EE###EE#####", "#####EEEEEEE#####",
                            "######EEEEE######", "#################", "#################", "#################",
                            "#################")
                    .aisle("AAAAAAAAAAAAAAAAA", "##BAACDDDDDCAAB##", "#####CDD@XDC#####", "#####CCDDDCC#####",
                            "######C###C######", "#################", "#################", "#################",
                            "#######EEE#######", "#######EEE#######", "#######EEE#######", "#################",
                            "#################", "#################", "#################", "#################",
                            "#################")
                    .aisle("AAAAAAAAAAAAAAAAA", "###BB#######BB###", "#################", "#################",
                            "#################", "#################", "#################", "#################",
                            "#################", "#################", "#################", "#################",
                            "#################", "#################", "#################", "#################",
                            "#################")
                    .where("A", Predicates.blocks(BotaniaBlocks.livingrockBrick))
                    .where("#", Predicates.any())
                    .where("B", Predicates.blocks(BotaniaBlocks.livingrockBrickSlab))
                    .where("C", Predicates.blocks(BotaniaBlocks.livingwoodLogStripped))
                    .where("D", Predicates.blocks(BotaniaBlocks.livingrockPolished)
                            .or(Predicates.autoAbilities(definition.getRecipeTypes()).setPreviewCount(0)))
                    .where("E", Predicates.blocks(BotaniaBlocks.manaGlass))
                    .where("F", Predicates.blocks(BotaniaBlocks.elfGlass))
                    .where("G", Predicates.blocks(BotaniaBlocks.bifrostPerm))
                    .where("X", Predicates.abilities(CMPartsAbility.MANAHATCH))
                    .where("@", Predicates.controller(Predicates.blocks(definition.get())))
                    .build())

            .workableCasingModel(CTNHMana.id("block/casings/living_rock_casing"),
                    CTNHMana.id("block/overlay/manamachine"))
            .register();
    public final static MultiblockMachineDefinition MANA_FORCE_TRANSFORMER = REGISTRATE
            .multiblock("mana_force_transformer", holder -> new ManaForceTransformer(holder, 4))
            .cnLangValue("§b魔力操纵者")
            .tooltips(MFT_Lang)
            .appearanceBlock(() -> BotaniaBlocks.livingrockPolished)
            .rotationState(RotationState.NON_Y_AXIS)
            .recipeType(CMRecipeTypes.MANA_TRANSFORMER_RECIPES)
            .recipeModifiers(ManaForceTransformer::recipeModifier,
                    GTRecipeModifiers.ELECTRIC_OVERCLOCK.apply(OverclockingLogic.NON_PERFECT_OVERCLOCK_SUBTICK))
            .pattern(definition -> FactoryBlockPattern.start()
                    .aisle("A########BBBBB#########", "#######################", "#######################",
                            "#######################", "#######################", "#######################",
                            "#######################", "#######################", "#######################",
                            "#######################", "#######################", "#######################",
                            "#######################", "#######################")
                    .aisle("######BBBCDDDCBBB######", "#######################", "#######################",
                            "#######################", "#######################", "#######################",
                            "#######################", "#######################", "#######################",
                            "#######################", "#######################", "#######################",
                            "#######################", "#######################")
                    .aisle("####BBCEEEDFDEEECBB####", "#######################", "#######################",
                            "#######################", "#######################", "#######################",
                            "#######################", "#######################", "#######################",
                            "#######################", "#######################", "#######################",
                            "#######################", "#######################")
                    .aisle("###BCEEBBCDDDCBBEECB###", "#######################", "#######################",
                            "#######################", "#######################", "#######################",
                            "#######################", "#######################", "#######GGGGGGGGG#######",
                            "#######################", "#######################", "#######################",
                            "#######################", "#######################")
                    .aisle("##BCBBBHHBBBBBHHBBBCB##", "####GGG#########GGG####", "#######################",
                            "#######################", "#######################", "#######################",
                            "#######################", "#######################", "####GGGG#######GGGG####",
                            "########BBBBBBB########", "#######################", "#######################",
                            "#######################", "#######################")
                    .aisle("##BEBBBBBEEEEEBBBBBEB##", "####GBG#########GBG####", "#####B###########B#####",
                            "#####B###########B#####", "#####B###########B#####", "#####B###########B#####",
                            "#####B###########B#####", "#####B###########B#####", "####GB###########BG####",
                            "#####BBB#######BBB#####", "########BBBBBBB########", "#######################",
                            "#######################", "#######################")
                    .aisle("#BCEBBEEECICICEEEBBECB#", "####GGG#########GGG####", "#######################",
                            "#######################", "#######################", "#######################",
                            "#######################", "#######################", "####G#############G####",
                            "#####B###########B#####", "######BB#######BB######", "########BBBBBBB########",
                            "#######################", "#######################")
                    .aisle("#BEBHBEJIBBBBBIJEBHBEB#", "#######################", "#######################",
                            "#######################", "#######################", "#######################",
                            "#######################", "#######################", "###GG#############GG###",
                            "#####B###########B#####", "######B#########B######", "#######BB#####BB#######",
                            "#########BBBBB#########", "#######################")
                    .aisle("#BEBHBEIEEKKKEEIEBHBEB#", "########EBBBBBE########", "########EBLLLBE########",
                            "########EHLLLHE########", "########EILLLIE########", "########EHLLLHE########",
                            "########EBLLLBE########", "########EBHIHBE########", "###G####EEEEEEE####G###",
                            "####B#############B####", "#####B###########B#####", "######BB#######BB######",
                            "########B#####B########", "#########BBBBB#########")
                    .aisle("BCECBEJBEBBCBBEBJEBCECB", "########BIMIMIB########", "########B#####B########",
                            "########H#####H########", "########I#####I########", "########H#####H########",
                            "########B#####B########", "########BLLLLLB########", "###G####E#####E####G###",
                            "####B#############B####", "#####B###########B#####", "######B#########B######",
                            "#######B#######B#######", "########BLLLLLB########")
                    .aisle("BDDDBEIBBBECEBBBIEBDDDB", "########BMEIEMB########", "########L#ELE#L########",
                            "########L#ELE#L########", "########L#ELE#L########", "########L#ELE#L########",
                            "########L#ELE#L########", "########HLELELH########", "###G####E#ELE#E####G###",
                            "####B#####ELE#####B####", "#####B####ELE####B#####", "######B###ELE###B######",
                            "#######B##ELE##B#######", "########BLLLLLB########")
                    .aisle("BDFDBEJBBCCCCCBBJEBDFDB", "########BIIMIIB########", "########L#LFL#L########",
                            "########L#LFL#L########", "########L#LFL#L########", "########L#LFL#L########",
                            "########L#LFL#L########", "########ILLFLLI########", "###G####E#LFL#E####G###",
                            "####B#####LFL#####B####", "#####B####LFL####B#####", "######B###LFL###B######",
                            "#######B##LFL##B#######", "########BLLLLLB########")
                    .aisle("BDDDBEIBBBECEBBBIEBDDDB", "########BMEIEMB########", "########L#ELE#L########",
                            "########L#ELE#L########", "########L#ELE#L########", "########L#ELE#L########",
                            "########L#ELE#L########", "########HLELELH########", "###G####E#ELE#E####G###",
                            "####B#####ELE#####B####", "#####B####ELE####B#####", "######B###ELE###B######",
                            "#######B##ELE##B#######", "########BLLLLLB########")
                    .aisle("BCECBEJBEBBCBBEBJEBCECB", "########BIMIMIB########", "########B#####B########",
                            "########H#####H########", "########I#####I########", "########H#####H########",
                            "########B#####B########", "########BLLLLLB########", "###G####E#####E####G###",
                            "####B#############B####", "#####B###########B#####", "######B#########B######",
                            "#######B#######B#######", "########BLLLLLB########")
                    .aisle("#BEBHBEIEEBBBEEIEBHBEB#", "########EBB@BBE########", "########EBLLLBE########",
                            "########EHLLLHE########", "########EILLLIE########", "########EHLLLHE########",
                            "########EBLLLBE########", "########EBHIHBE########", "###G####EEEEEEE####G###",
                            "####B#############B####", "#####B###########B#####", "######BB#######BB######",
                            "########B#####B########", "#########BBBBB#########")
                    .aisle("#BEBHBEJIBBBBBIJEBHBEB#", "#######################", "#######################",
                            "#######################", "#######################", "#######################",
                            "#######################", "#######################", "###GG#############GG###",
                            "#####B###########B#####", "######B#########B######", "#######BB#####BB#######",
                            "#########BBBBB#########", "#######################")
                    .aisle("#BCEBBEEEJIJIJEEEBBECB#", "####GGG#########GGG####", "#######################",
                            "#######################", "#######################", "#######################",
                            "#######################", "#######################", "####G#############G####",
                            "#####B###########B#####", "######BB#######BB######", "########BBBBBBB########",
                            "#######################", "#######################")
                    .aisle("##BEBBBBBEEEEEBBBBBEB##", "####GBG#########GBG####", "#####B###########B#####",
                            "#####B###########B#####", "#####B###########B#####", "#####B###########B#####",
                            "#####B###########B#####", "#####B###########B#####", "####GB###########BG####",
                            "#####BBB#######BBB#####", "########BBBBBBB########", "#######################",
                            "#######################", "#######################")
                    .aisle("##BCBBBHHBBBBBHHBBBCB##", "####GGG#########GGG####", "#######################",
                            "#######################", "#######################", "#######################",
                            "#######################", "#######################", "####GGGG#######GGGG####",
                            "########BBBBBBB########", "#######################", "#######################",
                            "#######################", "#######################")
                    .aisle("###BCEEBBCDDDCBBEECB###", "#######################", "#######################",
                            "#######################", "#######################", "#######################",
                            "#######################", "#######################", "#######GGGGGGGGG#######",
                            "#######################", "#######################", "#######################",
                            "#######################", "#######################")
                    .aisle("####BBCEEEDFDEEECBB####", "#######################", "#######################",
                            "#######################", "#######################", "#######################",
                            "#######################", "#######################", "#######################",
                            "#######################", "#######################", "#######################",
                            "#######################", "#######################")
                    .aisle("######BBBCDDDCBBB######", "#######################", "#######################",
                            "#######################", "#######################", "#######################",
                            "#######################", "#######################", "#######################",
                            "#######################", "#######################", "#######################",
                            "#######################", "#######################")
                    .where("B", Predicates.blocks(LIVING_ROCK_CASING.get())
                            .or(Predicates.autoAbilities(definition.getRecipeTypes()))
                            .or(abilities(CMPartsAbility.MANAHATCH).setExactLimit(1)))
                    .where("I", Predicates.blocks(PURE_MAGIC_CALCULATE_CORE.get()))
                    .where("J", Predicates.blocks(Blocks.SEA_LANTERN))
                    .where("@", Predicates.controller(Predicates.blocks(definition.get())))
                    .where("F", Predicates.blocks(PURE_MAGIC_CALCULATE_CORE.get()))
                    .where("K", Predicates.blocks(BotaniaBlocks.livingrockPolished))
                    .where("E", Predicates.blocks(ORICHALCOS_FRAME.get()))
                    .where("G",
                            Predicates.blocks(ForgeRegistries.BLOCKS.getValue(
                                    new ResourceLocation("ars_nouveau:smooth_gilded_sourcestone_alternating_stairs"))))
                    .where("A", Predicates.any())
                    .where("M", Predicates.blocks(FABRIC.get()))
                    .where("D", Predicates.blocks(TERRA_STEEL_CASING.get()))
                    .where("#", Predicates.any())
                    .where("H", Predicates.blocks(MANA_REFINEMENT_CORE.get()))
                    .where("L", Predicates.blocks(ENHANCED_MANA_GLASS.get()))
                    .where("C", Predicates.blocks(ORICHALCOS_STEEL_CASING_GEARBOX.get()))
                    .build())

            .workableCasingModel(CTNHMana.id("block/casings/living_rock_casing"),
                    CTNHMana.id("block/overlay/manamachine"))
            .register();

    public static MultiblockMachineDefinition HELLFORGE = REGISTRATE.multiblock("hellforge", HellForgeMachine::new)
            .cnLangValue("§4工业狱火锻炉")
            .rotationState(RotationState.NON_Y_AXIS)
            .appearanceBlock(SOUL_LOCKING_CASING::get)
            .recipeTypes(CMRecipeTypes.HELL_FORGE_RECIPES)
            .tooltips(hellforgeLang)
            .pattern(definition -> FactoryBlockPattern.start()
                    .aisle("AAAAAAA", "B#####B", "B#####B", "B#####B", "B#####B", "B#####B", "B#####B", "B#####B",
                            "AAAAAAA", "AAAAAAA", "A#A#A#A")
                    .aisle("AAAAAAA", "#A###A#", "#A###A#", "#A###A#", "#A###A#", "#A###A#", "#A###A#", "#A###A#",
                            "AAAAAAA", "A#####A", "#######")
                    .aisle("AAAAAAA", "##CCC##", "##D#D##", "##BCB##", "##BEB##", "##B#B##", "##D#D##", "##D#D##",
                            "AAAAAAA", "A#AAA#A", "A#####A")
                    .aisle("AAAAAAA", "##CFC##", "###G###", "##CCC##", "##EHE##", "#######", "#######", "#######",
                            "AAAAAAA", "A#AIA#A", "#######")
                    .aisle("AAAAAAA", "##CCC##", "##D#D##", "##BCB##", "##BEB##", "##B#B##", "##D#D##", "##D#D##",
                            "AAAAAAA", "A#AAA#A", "A#####A")
                    .aisle("AAAAAAA", "#A###A#", "#A###A#", "#A###A#", "#A###A#", "#A###A#", "#A###A#", "#A###A#",
                            "AAAAAAA", "A#####A", "#######")
                    .aisle("AAA@XAA", "B#####B", "B#####B", "B#####B", "B#####B", "B#####B", "B#####B", "B#####B",
                            "AAAAAAA", "AAAAAAA", "A#A#A#A")
                    .where("A",
                            Predicates.blocks(SOUL_LOCKING_CASING.get())
                                    .or(Predicates.autoAbilities(definition.getRecipeTypes()).setPreviewCount(0)))
                    .where("B", Predicates.blocks(CHAIN))
                    .where("#", Predicates.any())
                    .where("C", Predicates.blocks(BloodMagicBlocks.DUNGEON_BRICK_SLAB.get()))
                    .where("D", Predicates.blocks(BloodMagicBlocks.HELLFORGED_BLOCK.get()))
                    .where("E", Predicates.blocks(BloodMagicBlocks.DUNGEON_BRICK_1.get()))
                    .where("F", Predicates.blocks(BloodMagicBlocks.DUNGEON_TILE.get()))
                    .where("G", Predicates.blocks(BloodMagicBlocks.DUNGEON_BRICK_WALL.get()))
                    .where("H", Predicates.blocks(BloodMagicFluids.LIFE_ESSENCE_BLOCK.get()))
                    .where("@", Predicates.controller(Predicates.blocks(definition.get())))
                    .where("X", Predicates.abilities(CMPartsAbility.MANAHATCH))
                    .where("I", Predicates.blocks(LAVA)).build())
            .workableCasingModel(CTNHMana.id("block/casings/soul_lock_blackcasing"),
                    CTNHMana.id("block/overlay/manamachine_bm"))
            .register();
    public final static MultiblockMachineDefinition WISHINGWILLER = REGISTRATE
            .multiblock("genshin_wishing_will", WishingWill::new)
            .cnLangValue("§b许愿池")
            .tooltips(addManaMachineTooltips(basemanamutiblockLang, 1))
            .appearanceBlock(() -> BotaniaBlocks.livingrockPolished)
            .rotationState(RotationState.NON_Y_AXIS)
            .recipeType(CMRecipeTypes.WISHING_RECIPES)
            .pattern(definition -> FactoryBlockPattern.start()
                    .aisle("ABA", "AAA", "AAA", "CAC")
                    .aisle("ABA", "D#D", "D#D", "CAC")
                    .aisle("ABA", "D#D", "D#D", "CAC")
                    .aisle("ABA", "D#D", "D#D", "CAC")
                    .aisle("ABA", "A@X", "AAA", "CAC")
                    .where("A", Predicates.blocks(BotaniaBlocks.livingrockPolished)
                            .or(Predicates.autoAbilities(definition.getRecipeTypes()))
                            .or(abilities(PartAbility.IMPORT_FLUIDS)))
                    .where("B", Predicates.blocks(CMBlocks.MANA_STEEL_CASING.get()))
                    .where("C", Predicates.blocks(BotaniaBlocks.livingrockBrickStairs))
                    .where("D", Predicates.frames(CMMaterials.ManaSteel))
                    .where("X", Predicates.abilities(CMPartsAbility.MANAHATCH))
                    .where("#", Predicates.any())
                    .where("@", Predicates.controller(Predicates.blocks(definition.get())))
                    .build())

            .workableCasingModel(BotaniaRL("block/polished_livingrock"),
                    GTCEu.id("block/multiblock/generator/large_steam_turbine"))
            .register();
    public final static MultiblockMachineDefinition ZENITH_MATRIX = REGISTRATE.multiblock("zenith_matrix",
            holder -> new ZENITH_MATRIX(holder))
            .cnLangValue("天顶矩阵")
            .appearanceBlock(() -> BotaniaBlocks.livingrockPolished)
            .rotationState(RotationState.NON_Y_AXIS)
            .recipeType(GTRecipeTypes.DUMMY_RECIPES)
            .pattern(definition -> FactoryBlockPattern.start()
                    .aisle("A####BBB##############BBBBB##############BBB#####",
                            "#################################################",
                            "#################################################",
                            "#################################################",
                            "#################################################",
                            "#################################################",
                            "#################################################",
                            "#################################################",
                            "#################################################",
                            "#################################################",
                            "#################################################",
                            "#################################################",
                            "#################################################",
                            "#################################################",
                            "#################################################",
                            "#################################################",
                            "#################################################",
                            "#################################################",
                            "#################################################",
                            "#################################################",
                            "#################################################",
                            "#################################################",
                            "#################################################",
                            "#################################################",
                            "#################################################",
                            "#################################################",
                            "#################################################",
                            "#################################################",
                            "#################################################",
                            "#################################################",
                            "#################################################",
                            "#################################################",
                            "#################################################",
                            "#################################################",
                            "#################################################",
                            "#################################################",
                            "#################################################",
                            "#################################################",
                            "#################################################",
                            "#################################################",
                            "#################################################",
                            "#################################################",
                            "#################################################",
                            "#################################################",
                            "#################################################",
                            "#################################################",
                            "#################################################",
                            "#################################################",
                            "#################################################",
                            "#################################################",
                            "#################################################",
                            "#################################################",
                            "#################################################",
                            "#################################################",
                            "#####BCB##############BBBBB##############BDB#####")
                    .aisle("###BBBCBBB###########BCCBDDB###########BBBDBBB###",
                            "#####BCB#################################BDB#####",
                            "#####BCB#################################BDB#####",
                            "#####BCB#################################BDB#####",
                            "#####BCB#################################BDB#####",
                            "#####BCB#################################BDB#####",
                            "#####BCB#################################BDB#####",
                            "#####BCB#################################BDB#####",
                            "#####BCB#################################BDB#####",
                            "#####BCB#################################BDB#####",
                            "#################################################",
                            "#################################################",
                            "#################################################",
                            "#################################################",
                            "#################################################",
                            "#################################################",
                            "#################################################",
                            "#################################################",
                            "#################################################",
                            "#################################################",
                            "#################################################",
                            "#################################################",
                            "#################################################",
                            "#################################################",
                            "#################################################",
                            "#################################################",
                            "#####################EEEEEEE#####################",
                            "#####################EEEEEEE#####################",
                            "#####################EEEEEEE#####################",
                            "#################################################",
                            "#################################################",
                            "#################################################",
                            "#################################################",
                            "#################################################",
                            "#################################################",
                            "#################################################",
                            "#################################################",
                            "#################################################",
                            "#################################################",
                            "#################################################",
                            "#################################################",
                            "#################################################",
                            "#################################################",
                            "#################################################",
                            "#################################################",
                            "#####BCB#################################BDB#####",
                            "#####BCB#################################BDB#####",
                            "#####BCB#################################BDB#####",
                            "#####BCB#################################BDB#####",
                            "#####BCB#################################BDB#####",
                            "#####BCB#################################BDB#####",
                            "#####BCB#################################BDB#####",
                            "#####BCB#################################BDB#####",
                            "#####BCB#################################BDB#####",
                            "###BBBCBBB###########BCCBDDB###########BBBDBBB###")
                    .aisle("##BBBBCBBBB########BBCBBEBBDBB########BBBBDBBBB##",
                            "###BB###BB#############################BB###BB###",
                            "###BB###BB#############################BB###BB###",
                            "###BB###BB#############################BB###BB###",
                            "###BB###BB#############################BB###BB###",
                            "###BB###BB#############################BB###BB###",
                            "###BB###BB#############################BB###BB###",
                            "###BB###BB#############################BB###BB###",
                            "###BB###BB#############################BB###BB###",
                            "###BB###BB#############################BB###BB###",
                            "#####BCB#################################BDB#####",
                            "#####BCB#################################BDB#####",
                            "#####BCB#################################BDB#####",
                            "#####BCB#################################BDB#####",
                            "#####BCB#################################BDB#####",
                            "#####BCB#################################BDB#####",
                            "#####BCB#################################BDB#####",
                            "#################################################",
                            "#################################################",
                            "#################################################",
                            "#################################################",
                            "#################################################",
                            "#################################################",
                            "#################################################",
                            "#################################################",
                            "#################################################",
                            "################EEEEE#######EEEEE################",
                            "################EEEEE#######EEEEE################",
                            "################EEEEE#######EEEEE################",
                            "#################################################",
                            "#################################################",
                            "#################################################",
                            "#################################################",
                            "#################################################",
                            "#################################################",
                            "#################################################",
                            "#################################################",
                            "#################################################",
                            "#####BCB#################################BDB#####",
                            "#####BCB#################################BDB#####",
                            "#####BCB#################################BDB#####",
                            "#####BCB#################################BDB#####",
                            "#####BCB#################################BDB#####",
                            "#####BCB#################################BDB#####",
                            "#####BCB#################################BDB#####",
                            "###BB###BB#############################BB###BB###",
                            "###BB###BB#############################BB###BB###",
                            "###BB###BB#############################BB###BB###",
                            "###BB###BB#############################BB###BB###",
                            "###BB###BB#############################BB###BB###",
                            "###BB###BB#############################BB###BB###",
                            "###BB###BB#############################BB###BB###",
                            "###BB###BB#############################BB###BB###",
                            "###BB###BB#############################BB###BB###",
                            "##BBBBCBBBB########BBCBBBBBDBB########BBBBDBBBB##")
                    .aisle("#BBBBBCBBBBB#####BBCCBFFEFFBDDBB#####BBBBBDBBBBB#",
                            "##B#######B###########################B#######B##",
                            "##B#######B###########################B#######B##",
                            "##B#######B###########################B#######B##",
                            "##B#######B###########################B#######B##",
                            "##B#######B###########################B#######B##",
                            "##B#######B###########################B#######B##",
                            "##B#######B###########################B#######B##",
                            "##B#######B###########################B#######B##",
                            "##B#######B###########################B#######B##",
                            "###BB###BB#############################BB###BB###",
                            "###BB###BB#############################BB###BB###",
                            "###BB###BB#############################BB###BB###",
                            "###BB###BB#############################BB###BB###",
                            "###BB###BB#############################BB###BB###",
                            "###BB###BB#############################BB###BB###",
                            "###BB###BB#############################BB###BB###",
                            "#####BCB#################################BDB#####",
                            "#####BCB#################################BDB#####",
                            "#####BCB#################################BDB#####",
                            "#####BCB#################################BDB#####",
                            "#####BCB#################################BDB#####",
                            "#################################################",
                            "#################################################",
                            "#################################################",
                            "#################################################",
                            "#############EEE#################EEE#############",
                            "#############EEE#################EEE#############",
                            "#############EEE#################EEE#############",
                            "#################################################",
                            "#################################################",
                            "#################################################",
                            "#################################################",
                            "#####BCB#################################BDB#####",
                            "#####BCB#################################BDB#####",
                            "#####BCB#################################BDB#####",
                            "#####BCB#################################BDB#####",
                            "#####BCB#################################BDB#####",
                            "###BB###BB#############################BB###BB###",
                            "###BB###BB#############################BB###BB###",
                            "###BB###BB#############################BB###BB###",
                            "###BB###BB#############################BB###BB###",
                            "###BB###BB#############################BB###BB###",
                            "###BB###BB#############################BB###BB###",
                            "###BB###BB#############################BB###BB###",
                            "##B#######B###########################B#######B##",
                            "##B#######B###########################B#######B##",
                            "##B#######B###########################B#######B##",
                            "##B#######B###########################B#######B##",
                            "##B#######B###########################B#######B##",
                            "##B#######B###########################B#######B##",
                            "##B#######B###########################B#######B##",
                            "##B#######B###########################B#######B##",
                            "##B#######B###########################B#######B##",
                            "#BBBBBCBBBBB#####BBCCB#####BDDBB#####BBBBBDBBBBB#")
                    .aisle("#BBBBBCBBBBB###BBCCBBFFFEFFFBBDDBB###BBBBBDBBBBB#",
                            "##B#######B###########################B#######B##",
                            "##B#######B###########################B#######B##",
                            "##B#######B###########################B#######B##",
                            "##B#######B###########################B#######B##",
                            "##B#######B###########################B#######B##",
                            "##B#######B###########################B#######B##",
                            "##B#######B###########################B#######B##",
                            "##B#######B###########################B#######B##",
                            "##B#######B###########################B#######B##",
                            "###B#####B#############################B#####B###",
                            "###B#####B#############################B#####B###",
                            "###B#####B#############################B#####B###",
                            "###B#####B#############################B#####B###",
                            "###B#####B#############################B#####B###",
                            "###B#####B#############################B#####B###",
                            "###B#####B#############################B#####B###",
                            "####B###B###############################B###B####",
                            "####B###B###############################B###B####",
                            "####B###B###############################B###B####",
                            "####B###B###############################B###B####",
                            "####B###B###############################B###B####",
                            "#####BCB#################################BDB#####",
                            "#####BCB#################################BDB#####",
                            "#####BCB#################################BDB#####",
                            "#################################################",
                            "###########EE#######################EE###########",
                            "###########EE#######################EE###########",
                            "###########EE#######################EE###########",
                            "#################################################",
                            "#####BCB#################################BDB#####",
                            "#####BCB#################################BDB#####",
                            "#####BCB#################################BDB#####",
                            "####B###B###############################B###B####",
                            "####B###B###############################B###B####",
                            "####B###B###############################B###B####",
                            "####B###B###############################B###B####",
                            "####B###B###############################B###B####",
                            "###B#####B#############################B#####B###",
                            "###B#####B#############################B#####B###",
                            "###B#####B#############################B#####B###",
                            "###B#####B#############################B#####B###",
                            "###B#####B#############################B#####B###",
                            "###B#####B#############################B#####B###",
                            "###B#####B#############################B#####B###",
                            "##B#######B###########################B#######B##",
                            "##B#######B###########################B#######B##",
                            "##B#######B###########################B#######B##",
                            "##B#######B###########################B#######B##",
                            "##B#######B###########################B#######B##",
                            "##B#######B###########################B#######B##",
                            "##B#######B###########################B#######B##",
                            "##B#######B###########################B#######B##",
                            "##B#######B###########################B#######B##",
                            "#BBBBBCBBBBB###BBCCBB#######BBDDBB###BBBBBDBBBBB#")
                    .aisle("BBBBBBCBBBBBBBBCCBBFFFFFEFFFFFBBDDBBBBBBBBDBBBBBB",
                            "#B#########B#########################B#########B#",
                            "#B#########B#########################B#########B#",
                            "#B#########B#########################B#########B#",
                            "#B#########B#########################B#########B#",
                            "#B#########B#########################B#########B#",
                            "#B#########B#########################B#########B#",
                            "#B#########B#########################B#########B#",
                            "#B#########B#########################B#########B#",
                            "#B#########B#########################B#########B#",
                            "##B#######B###########################B#######B##",
                            "##B#######B###########################B#######B##",
                            "##B#######B###########################B#######B##",
                            "##B#######B###########################B#######B##",
                            "##B#######B###########################B#######B##",
                            "##B#######B###########################B#######B##",
                            "##B#######B###########################B#######B##",
                            "###B#####B#############################B#####B###",
                            "###B#####B#############################B#####B###",
                            "###B#####B#############################B#####B###",
                            "###B#####B#############################B#####B###",
                            "###B#####B#############################B#####B###",
                            "####B###B###############################B###B####",
                            "####B###B###############################B###B####",
                            "####B###B###############################B###B####",
                            "#####BCB#################################BDB#####",
                            "#####BCB#EE###########################EE#BDB#####",
                            "#####BCB#EE###########################EE#BDB#####",
                            "#####BCB#EE###########################EE#BDB#####",
                            "#####BCB#################################BDB#####",
                            "####B###B###############################B###B####",
                            "####B###B###############################B###B####",
                            "####B###B###############################B###B####",
                            "###B#####B#############################B#####B###",
                            "###B#####B#############################B#####B###",
                            "###B#####B#############################B#####B###",
                            "###B#####B#############################B#####B###",
                            "###B#####B#############################B#####B###",
                            "##B#######B###########################B#######B##",
                            "##B#######B###########################B#######B##",
                            "##B#######B###########################B#######B##",
                            "##B#######B###########################B#######B##",
                            "##B#######B###########################B#######B##",
                            "##B#######B###########################B#######B##",
                            "##B#######B###########################B#######B##",
                            "#B#########B#########################B#########B#",
                            "#B#########B#########################B#########B#",
                            "#B#########B#########################B#########B#",
                            "#B#########B#########################B#########B#",
                            "#B#########B#########################B#########B#",
                            "#B#########B#########################B#########B#",
                            "#B#########B#########################B#########B#",
                            "#B#########B#########################B#########B#",
                            "#B#########B#########################B#########B#",
                            "BBBBBBCBBBBBBBBCCBB###########BBDDBBBBBBBBDBBBBBB")
                    .aisle("BCCCCCCCCCCCCCCBBFFFFFFFEFFFFFFFBBDDDDDDDDDDDDDDB",
                            "#C####C####C#########################D####D####D#",
                            "#C####C####C#########################D####D####D#",
                            "#C####C####C#########################D####D####D#",
                            "#C####C####C#########################D####D####D#",
                            "#C####C####C#########################D####D####D#",
                            "#C####C####C#########################D####D####D#",
                            "#C####C####C#########################D####D####D#",
                            "#C####C####C#########################D####D####D#",
                            "#C####C####C#########################D####D####D#",
                            "##C###C###C###########################D###D###D##",
                            "##C###C###C###########################D###D###D##",
                            "##C###C###C###########################D###D###D##",
                            "##C###C###C###########################D###D###D##",
                            "##C###C###C###########################D###D###D##",
                            "##C###C###C###########################D###D###D##",
                            "##C###C###C###########################D###D###D##",
                            "###C##C##C#############################D##D##D###",
                            "###C##C##C#############################D##D##D###",
                            "###C##C##C#############################D##D##D###",
                            "###C##C##C#############################D##D##D###",
                            "###C##C##C#############################D##D##D###",
                            "####C#C#C###############################D#D#D####",
                            "####C#C#C###############################D#D#D####",
                            "####C#C#C###############################D#D#D####",
                            "#####CCC#################################DDD#####",
                            "#####CCCE###############################EDDD#####",
                            "#####CCCE###############################EDDD#####",
                            "#####CCCE###############################EDDD#####",
                            "#####CCC#################################DDD#####",
                            "####C#C#C###############################D#D#D####",
                            "####C#C#C###############################D#D#D####",
                            "####C#C#C###############################D#D#D####",
                            "###C##C##C#############################D##D##D###",
                            "###C##C##C#############################D##D##D###",
                            "###C##C##C#############################D##D##D###",
                            "###C##C##C#############################D##D##D###",
                            "###C##C##C#############################D##D##D###",
                            "##C###C###C###########################D###D###D##",
                            "##C###C###C###########################D###D###D##",
                            "##C###C###C###########################D###D###D##",
                            "##C###C###C###########################D###D###D##",
                            "##C###C###C###########################D###D###D##",
                            "##C###C###C###########################D###D###D##",
                            "##C###C###C###########################D###D###D##",
                            "#C####C####C#########################D####D####D#",
                            "#C####C####C#########################D####D####D#",
                            "#C####C####C#########################D####D####D#",
                            "#C####C####C#########################D####D####D#",
                            "#C####C####C#########################D####D####D#",
                            "#C####C####C#########################D####D####D#",
                            "#C####C####C#########################D####D####D#",
                            "#C####C####C#########################D####D####D#",
                            "#C####C####C#########################D####D####D#",
                            "CCCCCCCCCCCCCCCBB###############BBDDDDDDDDDDDDDDD")
                    .aisle("BBBBBBCBBBBBBBBFFFFFFFFFEFFFFFFFFFBBBBBBBBDBBBBBB",
                            "#B#########B#########################B#########B#",
                            "#B#########B#########################B#########B#",
                            "#B#########B#########################B#########B#",
                            "#B#########B#########################B#########B#",
                            "#B#########B#########################B#########B#",
                            "#B#########B#########################B#########B#",
                            "#B#########B#########################B#########B#",
                            "#B#########B#########################B#########B#",
                            "#B#########B#########################B#########B#",
                            "##B#######B###########################B#######B##",
                            "##B#######B###########################B#######B##",
                            "##B#######B###########################B#######B##",
                            "##B#######B###########################B#######B##",
                            "##B#######B###########################B#######B##",
                            "##B#######B###########################B#######B##",
                            "##B#######B###########################B#######B##",
                            "###B#####B#############################B#####B###",
                            "###B#####B#############################B#####B###",
                            "###B#####B#############################B#####B###",
                            "###B#####B#############################B#####B###",
                            "###B#####B#############################B#####B###",
                            "####B###B###############################B###B####",
                            "####B###B###############################B###B####",
                            "####B###B###############################B###B####",
                            "#####BCB#################################BDB#####",
                            "#####BCB#################################BDB#####",
                            "#####BCB#################################BDB#####",
                            "#####BCB#################################BDB#####",
                            "#####BCB#################################BDB#####",
                            "####B###B###############################B###B####",
                            "####B###B###############################B###B####",
                            "####B###B###############################B###B####",
                            "###B#####B#############################B#####B###",
                            "###B#####B#############################B#####B###",
                            "###B#####B#############################B#####B###",
                            "###B#####B#############################B#####B###",
                            "###B#####B#############################B#####B###",
                            "##B#######B###########################B#######B##",
                            "##B#######B###########################B#######B##",
                            "##B#######B###########################B#######B##",
                            "##B#######B###########################B#######B##",
                            "##B#######B###########################B#######B##",
                            "##B#######B###########################B#######B##",
                            "##B#######B###########################B#######B##",
                            "#B#########B#########################B#########B#",
                            "#B#########B#########################B#########B#",
                            "#B#########B#########################B#########B#",
                            "#B#########B#########################B#########B#",
                            "#B#########B#########################B#########B#",
                            "#B#########B#########################B#########B#",
                            "#B#########B#########################B#########B#",
                            "#B#########B#########################B#########B#",
                            "#B#########B#########################B#########B#",
                            "BBBBBBCBBBBBBBB###################BBBBBBBBDBBBBBB")
                    .aisle("#BBBBBCBBBBBFFFFFFFFFFFFEFFFFFFFFFFFFBBBBBDBBBBB#",
                            "##B#######B###########################B#######B##",
                            "##B#######B###########################B#######B##",
                            "##B#######B###########################B#######B##",
                            "##B#######B###########################B#######B##",
                            "##B#######B###########################B#######B##",
                            "##B#######B###########################B#######B##",
                            "##B#######B###########################B#######B##",
                            "##B#######B###########################B#######B##",
                            "##B#######B###########################B#######B##",
                            "###B#####B#############################B#####B###",
                            "###B#####B#############################B#####B###",
                            "###B#####B#############################B#####B###",
                            "###B#####B#############################B#####B###",
                            "###B#####B#############################B#####B###",
                            "###B#####B#############################B#####B###",
                            "###B#####B#############################B#####B###",
                            "####B###B###############################B###B####",
                            "####B###B###############################B###B####",
                            "####B###B###############################B###B####",
                            "####B###B###############################B###B####",
                            "####B###B###############################B###B####",
                            "#####BCB#################################BDB#####",
                            "#####BCB#################################BDB#####",
                            "#####BCB#################################BDB#####",
                            "#################################################",
                            "######G###################################H######",
                            "######G###################################H######",
                            "######G###################################H######",
                            "#################################################",
                            "#####BCB#################################BDB#####",
                            "#####BCB#################################BDB#####",
                            "#####BCB#################################BDB#####",
                            "####B###B###############################B###B####",
                            "####B###B###############################B###B####",
                            "####B###B###############################B###B####",
                            "####B###B###############################B###B####",
                            "####B###B###############################B###B####",
                            "###B#####B#############################B#####B###",
                            "###B#####B#############################B#####B###",
                            "###B#####B#############################B#####B###",
                            "###B#####B#############################B#####B###",
                            "###B#####B#############################B#####B###",
                            "###B#####B#############################B#####B###",
                            "###B#####B#############################B#####B###",
                            "##B#######B###########################B#######B##",
                            "##B#######B###########################B#######B##",
                            "##B#######B###########################B#######B##",
                            "##B#######B###########################B#######B##",
                            "##B#######B###########################B#######B##",
                            "##B#######B###########################B#######B##",
                            "##B#######B###########################B#######B##",
                            "##B#######B###########################B#######B##",
                            "##B#######B###########################B#######B##",
                            "#BBBBBCBBBBB#########################BBBBBDBBBBB#")
                    .aisle("#BBBBBCBBBBBFFFFFFFFFFFFEFFFFFFFFFFFFBBBBBDBBBBB#",
                            "##B#######B###########################B#######B##",
                            "##B#######B###########################B#######B##",
                            "##B#######B###########################B#######B##",
                            "##B#######B###########################B#######B##",
                            "##B#######B###########################B#######B##",
                            "##B#######B###########################B#######B##",
                            "##B#######B###########################B#######B##",
                            "##B#######B###########################B#######B##",
                            "##B#######B###########################B#######B##",
                            "###BB###BB#############################BB###BB###",
                            "###BB###BB#############################BB###BB###",
                            "###BB###BB#############################BB###BB###",
                            "###BB###BB#############################BB###BB###",
                            "###BB###BB#############################BB###BB###",
                            "###BB###BB#############################BB###BB###",
                            "###BB###BB#############################BB###BB###",
                            "#####BCB#################################BDB#####",
                            "#####BCB#################################BDB#####",
                            "#####BCB#################################BDB#####",
                            "#####BCB#################################BDB#####",
                            "#####BCB#################################BDB#####",
                            "#################################################",
                            "#################################################",
                            "#################################################",
                            "#################################################",
                            "#####G#####################################H#####",
                            "#####G#####################################H#####",
                            "#####G#####################################H#####",
                            "#################################################",
                            "#################################################",
                            "#################################################",
                            "#################################################",
                            "#####BCB#################################BDB#####",
                            "#####BCB#################################BDB#####",
                            "#####BCB#################################BDB#####",
                            "#####BCB#################################BDB#####",
                            "#####BCB#################################BDB#####",
                            "###BB###BB#############################BB###BB###",
                            "###BB###BB#############################BB###BB###",
                            "###BB###BB#############################BB###BB###",
                            "###BB###BB#############################BB###BB###",
                            "###BB###BB#############################BB###BB###",
                            "###BB###BB#############################BB###BB###",
                            "###BB###BB#############################BB###BB###",
                            "##B#######B###########################B#######B##",
                            "##B#######B###########################B#######B##",
                            "##B#######B###########################B#######B##",
                            "##B#######B###########################B#######B##",
                            "##B#######B###########################B#######B##",
                            "##B#######B###########################B#######B##",
                            "##B#######B###########################B#######B##",
                            "##B#######B###########################B#######B##",
                            "##B#######B###########################B#######B##",
                            "#BBBBBCBBBBB#########################BBBBBDBBBBB#")
                    .aisle("##BBBBCBBBBFFFFFFFFFFFFFEFFFFFFFFFFFFFBBBBDBBBB##",
                            "###BB###BB#############################BB###BB###",
                            "###BB###BB#############################BB###BB###",
                            "###BB###BB#############################BB###BB###",
                            "###BB###BB#############################BB###BB###",
                            "###BB###BB#############################BB###BB###",
                            "###BB###BB#############################BB###BB###",
                            "###BB###BB#############################BB###BB###",
                            "###BB###BB#############################BB###BB###",
                            "###BB###BB#############################BB###BB###",
                            "#####BCB#################################BDB#####",
                            "#####BCB#################################BDB#####",
                            "#####BCB#################################BDB#####",
                            "#####BCB#################################BDB#####",
                            "#####BCB#################################BDB#####",
                            "#####BCB#################################BDB#####",
                            "#####BCB#################################BDB#####",
                            "#################################################",
                            "#################################################",
                            "#################################################",
                            "#################################################",
                            "#################################################",
                            "#################################################",
                            "#################################################",
                            "#################################################",
                            "#################################################",
                            "#####G#####################################H#####",
                            "#####G#####################################H#####",
                            "#####G#####################################H#####",
                            "#################################################",
                            "#################################################",
                            "#################################################",
                            "#################################################",
                            "#################################################",
                            "#################################################",
                            "#################################################",
                            "#################################################",
                            "#################################################",
                            "#####BCB#################################BDB#####",
                            "#####BCB#################################BDB#####",
                            "#####BCB#################################BDB#####",
                            "#####BCB#################################BDB#####",
                            "#####BCB#################################BDB#####",
                            "#####BCB#################################BDB#####",
                            "#####BCB#################################BDB#####",
                            "###BB###BB#############################BB###BB###",
                            "###BB###BB#############################BB###BB###",
                            "###BB###BB#############################BB###BB###",
                            "###BB###BB#############################BB###BB###",
                            "###BB###BB#############################BB###BB###",
                            "###BB###BB#############################BB###BB###",
                            "###BB###BB#############################BB###BB###",
                            "###BB###BB#############################BB###BB###",
                            "###BB###BB#############################BB###BB###",
                            "##BBBBCBBBB###########################BBBBDBBBB##")
                    .aisle("###BBBCBBBFFFFFFFFFFFFFFEFFFFFFFFFFFFFFBBBDBBB###",
                            "#####BCB#################################BDB#####",
                            "#####BCB#################################BDB#####",
                            "#####BCB#################################BDB#####",
                            "#####BCB#################################BDB#####",
                            "#####BCB#################################BDB#####",
                            "#####BCB#################################BDB#####",
                            "#####BCB#################################BDB#####",
                            "#####BCB#################################BDB#####",
                            "#####BCB#################################BDB#####",
                            "#################################################",
                            "#################################################",
                            "#################################################",
                            "#################################################",
                            "#################################################",
                            "#################################################",
                            "#################################################",
                            "#################################################",
                            "#################################################",
                            "#################################################",
                            "#################################################",
                            "#################################################",
                            "#################################################",
                            "#################################################",
                            "#################################################",
                            "#################################################",
                            "####G#######################################H####",
                            "####G#######################################H####",
                            "####G#######################################H####",
                            "#################################################",
                            "#################################################",
                            "#################################################",
                            "#################################################",
                            "#################################################",
                            "#################################################",
                            "#################################################",
                            "#################################################",
                            "#################################################",
                            "#################################################",
                            "#################################################",
                            "#################################################",
                            "#################################################",
                            "#################################################",
                            "#################################################",
                            "#################################################",
                            "#####BCB#################################BDB#####",
                            "#####BCB#################################BDB#####",
                            "#####BCB#################################BDB#####",
                            "#####BCB#################################BDB#####",
                            "#####BCB#################################BDB#####",
                            "#####BCB#################################BDB#####",
                            "#####BCB#################################BDB#####",
                            "#####BCB#################################BDB#####",
                            "#####BCB#################################BDB#####",
                            "###BBBCBBB#############################BBBDBBB###")
                    .aisle("#####BCBFFFFFFFFFFFFFFFFEFFFFFFFFFFFFFFFFBDB#####",
                            "#################################################",
                            "#################################################",
                            "#################################################",
                            "#################################################",
                            "#################################################",
                            "#################################################",
                            "#################################################",
                            "#################################################",
                            "#################################################",
                            "#################################################",
                            "#################################################",
                            "#################################################",
                            "#################################################",
                            "#################################################",
                            "#################################################",
                            "#################################################",
                            "#################################################",
                            "#################################################",
                            "#################################################",
                            "#################################################",
                            "#################################################",
                            "#################################################",
                            "#################################################",
                            "#################################################",
                            "#################################################",
                            "####G#######################################H####",
                            "####G#######################################H####",
                            "####G#######################################H####",
                            "#################################################",
                            "#################################################",
                            "#################################################",
                            "#################################################",
                            "#################################################",
                            "#################################################",
                            "#################################################",
                            "#################################################",
                            "#################################################",
                            "#################################################",
                            "#################################################",
                            "#################################################",
                            "#################################################",
                            "#################################################",
                            "#################################################",
                            "#################################################",
                            "#################################################",
                            "#################################################",
                            "#################################################",
                            "#################################################",
                            "#################################################",
                            "#################################################",
                            "#################################################",
                            "#################################################",
                            "#################################################",
                            "#####BCB#################################BDB#####")
                    .aisle("#####BCBFFFFFFFFFFFFFFFFEFFFFFFFFFFFFFFFFBDB#####",
                            "#################################################",
                            "#################################################",
                            "#################################################",
                            "#################################################",
                            "#################################################",
                            "#################################################",
                            "#################################################",
                            "#################################################",
                            "#################################################",
                            "#################################################",
                            "#################################################",
                            "#################################################",
                            "#################################################",
                            "#################################################",
                            "#################################################",
                            "#################################################",
                            "#################################################",
                            "#################################################",
                            "#################################################",
                            "#################################################",
                            "#################################################",
                            "#################################################",
                            "#################################################",
                            "#################################################",
                            "#################################################",
                            "###G#########################################H###",
                            "###G#########################################H###",
                            "###G#########################################H###",
                            "#################################################",
                            "#################################################",
                            "#################################################",
                            "#################################################",
                            "#################################################",
                            "#################################################",
                            "#################################################",
                            "#################################################",
                            "#################################################",
                            "#################################################",
                            "#################################################",
                            "#################################################",
                            "#################################################",
                            "#################################################",
                            "#################################################",
                            "#################################################",
                            "#################################################",
                            "#################################################",
                            "#################################################",
                            "#################################################",
                            "#################################################",
                            "#################################################",
                            "#################################################",
                            "#################################################",
                            "#################################################",
                            "#####BCB#################################BDB#####")
                    .aisle("#####BCBFFFFFFFFFFFFFFFFEFFFFFFFFFFFFFFFFBDB#####",
                            "#################################################",
                            "#################################################",
                            "#################################################",
                            "#################################################",
                            "#################################################",
                            "#################################################",
                            "#################################################",
                            "#################################################",
                            "#################################################",
                            "#################################################",
                            "#################################################",
                            "#################################################",
                            "#################################################",
                            "#################################################",
                            "#################################################",
                            "#################################################",
                            "#################################################",
                            "#################################################",
                            "#################################################",
                            "#################################################",
                            "#################################################",
                            "#################################################",
                            "#################################################",
                            "#################################################",
                            "#################################################",
                            "###G#########################################H###",
                            "###G#########################################H###",
                            "###G#########################################H###",
                            "#################################################",
                            "#################################################",
                            "#################################################",
                            "#################################################",
                            "#################################################",
                            "#################################################",
                            "#################################################",
                            "#################################################",
                            "#################################################",
                            "#################################################",
                            "#################################################",
                            "#################################################",
                            "#################################################",
                            "#################################################",
                            "#################################################",
                            "#################################################",
                            "#################################################",
                            "#################################################",
                            "#################################################",
                            "#################################################",
                            "#################################################",
                            "#################################################",
                            "#################################################",
                            "#################################################",
                            "#################################################",
                            "#####BCB#################################BDB#####")
                    .aisle("####BCBFFFFFFFFFFFFFFFFFEFFFFFFFFFFFFFFFFFBDB####",
                            "#################################################",
                            "#################################################",
                            "#################################################",
