package com.moguang.ctnhmana.registry;


import com.gregtechceu.gtceu.GTCEu;
import com.gregtechceu.gtceu.api.data.RotationState;
import com.gregtechceu.gtceu.api.machine.MultiblockMachineDefinition;
import com.gregtechceu.gtceu.api.machine.multiblock.PartAbility;
import com.gregtechceu.gtceu.api.machine.property.GTMachineModelProperties;
import com.gregtechceu.gtceu.api.machine.trait.RecipeLogic;
import com.gregtechceu.gtceu.api.pattern.FactoryBlockPattern;
import com.gregtechceu.gtceu.api.pattern.Predicates;
import com.gregtechceu.gtceu.api.recipe.OverclockingLogic;
import com.gregtechceu.gtceu.common.data.GTRecipeModifiers;
import com.gregtechceu.gtceu.common.data.GTRecipeTypes;
import com.moguang.ctnhmana.CTNHMana;
import com.moguang.ctnhmana.client.render.ZenithMatrixBlockEntityRender;
import com.moguang.ctnhmana.common.Mutiblock.BaseManaMachine;
import com.moguang.ctnhmana.common.Mutiblock.ZENITH_MATRIX;
import com.moguang.ctnhmana.common.Mutiblock.parts.CMPartsAbility;
import net.minecraft.resources.ResourceLocation;
import net.minecraftforge.registries.ForgeRegistries;
import vazkii.botania.common.block.BotaniaBlocks;

import static com.gregtechceu.gtceu.api.pattern.Predicates.abilities;
import static com.gregtechceu.gtceu.common.data.GTBlocks.*;
import static com.gregtechceu.gtceu.common.data.models.GTMachineModels.createWorkableCasingMachineModel;
import static com.moguang.ctnhmana.CTNHMana.REGISTRATE;
import static com.moguang.ctnhmana.data.lang.ChineseLangHandler.basemanamutiblockLang;
import static com.moguang.ctnhmana.registry.CMBlocks.*;
import static com.moguang.ctnhmana.utils.ModUtils.BotaniaRL;
import com.moguang.ctnhmana.common.*;
public class CMMultiblockMachines {
    static {
        REGISTRATE.creativeModeTab(() -> CMCreativeModeTabs.MACHINE);
    }

    public static void init() {
//I LOVE U
    }
    public final static MultiblockMachineDefinition MANA_MACERATOR = REGISTRATE.multiblock("mana_macerator",holder-> new BaseManaMachine(holder,1))
            .cnLangValue("魔力卷板机")
            .rotationState(RotationState.NON_Y_AXIS)
            .recipeType(GTRecipeTypes.MACERATOR_RECIPES)
            .appearanceBlock(CASING_STAINLESS_CLEAN)
            .recipeModifiers(BaseManaMachine::recipeModifier, GTRecipeModifiers.ELECTRIC_OVERCLOCK.apply(OverclockingLogic.PERFECT_OVERCLOCK_SUBTICK))
            .pattern(definition -> FactoryBlockPattern.start()
                    .aisle("ABBA", "AAAA", "ABBA")
                    .aisle("ABBA", "ACCA", "ABBA")
                    .aisle("ABBA", "A@DA", "ABBA")
                    .where("A", Predicates.blocks(BotaniaBlocks.livingrockPolished)
                            .or(Predicates.autoAbilities(definition.getRecipeTypes())))
                    .where("B", Predicates.blocks(BotaniaBlocks.livingrockPolished))
                    .where("C", Predicates.blocks(CASING_STEEL_GEARBOX.get()))
                    .where("D", abilities(CMPartsAbility.MANAHATCH))
                    .where("@", Predicates.controller(Predicates.blocks(definition.get())))
                    .build()
            )
            .workableCasingModel(BotaniaRL("block/polished_livingrock"), GTCEu.id("block/multiblock/generator/large_steam_turbine"))
            .register();
    public final static MultiblockMachineDefinition ZENITH_MATRIX = REGISTRATE.multiblock("zenith_matrix",holder-> new ZENITH_MATRIX(holder))
            .cnLangValue("天顶矩阵")
            .rotationState(RotationState.NON_Y_AXIS)

            .recipeType(GTRecipeTypes.DUMMY_RECIPES)


            .pattern(definition -> FactoryBlockPattern.start()
                    .aisle("A####BBB##############BBBBB##############BBB#####", "#################################################", "#################################################", "#################################################", "#################################################", "#################################################", "#################################################", "#################################################", "#################################################", "#################################################", "#################################################", "#################################################", "#################################################", "#################################################", "#################################################", "#################################################", "#################################################", "#################################################", "#################################################", "#################################################", "#################################################", "#################################################", "#################################################", "#################################################", "#################################################", "#################################################", "#################################################", "#################################################", "#################################################", "#################################################", "#################################################", "#################################################", "#################################################", "#################################################", "#################################################", "#################################################", "#################################################", "#################################################", "#################################################", "#################################################", "#################################################", "#################################################", "#################################################", "#################################################", "#################################################", "#################################################", "#################################################", "#################################################", "#################################################", "#################################################", "#################################################", "#################################################", "#################################################", "#################################################", "#####BCB##############BBBBB##############BDB#####")
                    .aisle("###BBBCBBB###########BCCBDDB###########BBBDBBB###", "#####BCB#################################BDB#####", "#####BCB#################################BDB#####", "#####BCB#################################BDB#####", "#####BCB#################################BDB#####", "#####BCB#################################BDB#####", "#####BCB#################################BDB#####", "#####BCB#################################BDB#####", "#####BCB#################################BDB#####", "#####BCB#################################BDB#####", "#################################################", "#################################################", "#################################################", "#################################################", "#################################################", "#################################################", "#################################################", "#################################################", "#################################################", "#################################################", "#################################################", "#################################################", "#################################################", "#################################################", "#################################################", "#################################################", "#####################EEEEEEE#####################", "#####################EEEEEEE#####################", "#####################EEEEEEE#####################", "#################################################", "#################################################", "#################################################", "#################################################", "#################################################", "#################################################", "#################################################", "#################################################", "#################################################", "#################################################", "#################################################", "#################################################", "#################################################", "#################################################", "#################################################", "#################################################", "#####BCB#################################BDB#####", "#####BCB#################################BDB#####", "#####BCB#################################BDB#####", "#####BCB#################################BDB#####", "#####BCB#################################BDB#####", "#####BCB#################################BDB#####", "#####BCB#################################BDB#####", "#####BCB#################################BDB#####", "#####BCB#################################BDB#####", "###BBBCBBB###########BCCBDDB###########BBBDBBB###")
                    .aisle("##BBBBCBBBB########BBCBBEBBDBB########BBBBDBBBB##", "###BB###BB#############################BB###BB###", "###BB###BB#############################BB###BB###", "###BB###BB#############################BB###BB###", "###BB###BB#############################BB###BB###", "###BB###BB#############################BB###BB###", "###BB###BB#############################BB###BB###", "###BB###BB#############################BB###BB###", "###BB###BB#############################BB###BB###", "###BB###BB#############################BB###BB###", "#####BCB#################################BDB#####", "#####BCB#################################BDB#####", "#####BCB#################################BDB#####", "#####BCB#################################BDB#####", "#####BCB#################################BDB#####", "#####BCB#################################BDB#####", "#####BCB#################################BDB#####", "#################################################", "#################################################", "#################################################", "#################################################", "#################################################", "#################################################", "#################################################", "#################################################", "#################################################", "################EEEEE#######EEEEE################", "################EEEEE#######EEEEE################", "################EEEEE#######EEEEE################", "#################################################", "#################################################", "#################################################", "#################################################", "#################################################", "#################################################", "#################################################", "#################################################", "#################################################", "#####BCB#################################BDB#####", "#####BCB#################################BDB#####", "#####BCB#################################BDB#####", "#####BCB#################################BDB#####", "#####BCB#################################BDB#####", "#####BCB#################################BDB#####", "#####BCB#################################BDB#####", "###BB###BB#############################BB###BB###", "###BB###BB#############################BB###BB###", "###BB###BB#############################BB###BB###", "###BB###BB#############################BB###BB###", "###BB###BB#############################BB###BB###", "###BB###BB#############################BB###BB###", "###BB###BB#############################BB###BB###", "###BB###BB#############################BB###BB###", "###BB###BB#############################BB###BB###", "##BBBBCBBBB########BBCBBBBBDBB########BBBBDBBBB##")
                    .aisle("#BBBBBCBBBBB#####BBCCBFFEFFBDDBB#####BBBBBDBBBBB#", "##B#######B###########################B#######B##", "##B#######B###########################B#######B##", "##B#######B###########################B#######B##", "##B#######B###########################B#######B##", "##B#######B###########################B#######B##", "##B#######B###########################B#######B##", "##B#######B###########################B#######B##", "##B#######B###########################B#######B##", "##B#######B###########################B#######B##", "###BB###BB#############################BB###BB###", "###BB###BB#############################BB###BB###", "###BB###BB#############################BB###BB###", "###BB###BB#############################BB###BB###", "###BB###BB#############################BB###BB###", "###BB###BB#############################BB###BB###", "###BB###BB#############################BB###BB###", "#####BCB#################################BDB#####", "#####BCB#################################BDB#####", "#####BCB#################################BDB#####", "#####BCB#################################BDB#####", "#####BCB#################################BDB#####", "#################################################", "#################################################", "#################################################", "#################################################", "#############EEE#################EEE#############", "#############EEE#################EEE#############", "#############EEE#################EEE#############", "#################################################", "#################################################", "#################################################", "#################################################", "#####BCB#################################BDB#####", "#####BCB#################################BDB#####", "#####BCB#################################BDB#####", "#####BCB#################################BDB#####", "#####BCB#################################BDB#####", "###BB###BB#############################BB###BB###", "###BB###BB#############################BB###BB###", "###BB###BB#############################BB###BB###", "###BB###BB#############################BB###BB###", "###BB###BB#############################BB###BB###", "###BB###BB#############################BB###BB###", "###BB###BB#############################BB###BB###", "##B#######B###########################B#######B##", "##B#######B###########################B#######B##", "##B#######B###########################B#######B##", "##B#######B###########################B#######B##", "##B#######B###########################B#######B##", "##B#######B###########################B#######B##", "##B#######B###########################B#######B##", "##B#######B###########################B#######B##", "##B#######B###########################B#######B##", "#BBBBBCBBBBB#####BBCCB#####BDDBB#####BBBBBDBBBBB#")
                    .aisle("#BBBBBCBBBBB###BBCCBBFFFEFFFBBDDBB###BBBBBDBBBBB#", "##B#######B###########################B#######B##", "##B#######B###########################B#######B##", "##B#######B###########################B#######B##", "##B#######B###########################B#######B##", "##B#######B###########################B#######B##", "##B#######B###########################B#######B##", "##B#######B###########################B#######B##", "##B#######B###########################B#######B##", "##B#######B###########################B#######B##", "###B#####B#############################B#####B###", "###B#####B#############################B#####B###", "###B#####B#############################B#####B###", "###B#####B#############################B#####B###", "###B#####B#############################B#####B###", "###B#####B#############################B#####B###", "###B#####B#############################B#####B###", "####B###B###############################B###B####", "####B###B###############################B###B####", "####B###B###############################B###B####", "####B###B###############################B###B####", "####B###B###############################B###B####", "#####BCB#################################BDB#####", "#####BCB#################################BDB#####", "#####BCB#################################BDB#####", "#################################################", "###########EE#######################EE###########", "###########EE#######################EE###########", "###########EE#######################EE###########", "#################################################", "#####BCB#################################BDB#####", "#####BCB#################################BDB#####", "#####BCB#################################BDB#####", "####B###B###############################B###B####", "####B###B###############################B###B####", "####B###B###############################B###B####", "####B###B###############################B###B####", "####B###B###############################B###B####", "###B#####B#############################B#####B###", "###B#####B#############################B#####B###", "###B#####B#############################B#####B###", "###B#####B#############################B#####B###", "###B#####B#############################B#####B###", "###B#####B#############################B#####B###", "###B#####B#############################B#####B###", "##B#######B###########################B#######B##", "##B#######B###########################B#######B##", "##B#######B###########################B#######B##", "##B#######B###########################B#######B##", "##B#######B###########################B#######B##", "##B#######B###########################B#######B##", "##B#######B###########################B#######B##", "##B#######B###########################B#######B##", "##B#######B###########################B#######B##", "#BBBBBCBBBBB###BBCCBB#######BBDDBB###BBBBBDBBBBB#")
                    .aisle("BBBBBBCBBBBBBBBCCBBFFFFFEFFFFFBBDDBBBBBBBBDBBBBBB", "#B#########B#########################B#########B#", "#B#########B#########################B#########B#", "#B#########B#########################B#########B#", "#B#########B#########################B#########B#", "#B#########B#########################B#########B#", "#B#########B#########################B#########B#", "#B#########B#########################B#########B#", "#B#########B#########################B#########B#", "#B#########B#########################B#########B#", "##B#######B###########################B#######B##", "##B#######B###########################B#######B##", "##B#######B###########################B#######B##", "##B#######B###########################B#######B##", "##B#######B###########################B#######B##", "##B#######B###########################B#######B##", "##B#######B###########################B#######B##", "###B#####B#############################B#####B###", "###B#####B#############################B#####B###", "###B#####B#############################B#####B###", "###B#####B#############################B#####B###", "###B#####B#############################B#####B###", "####B###B###############################B###B####", "####B###B###############################B###B####", "####B###B###############################B###B####", "#####BCB#################################BDB#####", "#####BCB#EE###########################EE#BDB#####", "#####BCB#EE###########################EE#BDB#####", "#####BCB#EE###########################EE#BDB#####", "#####BCB#################################BDB#####", "####B###B###############################B###B####", "####B###B###############################B###B####", "####B###B###############################B###B####", "###B#####B#############################B#####B###", "###B#####B#############################B#####B###", "###B#####B#############################B#####B###", "###B#####B#############################B#####B###", "###B#####B#############################B#####B###", "##B#######B###########################B#######B##", "##B#######B###########################B#######B##", "##B#######B###########################B#######B##", "##B#######B###########################B#######B##", "##B#######B###########################B#######B##", "##B#######B###########################B#######B##", "##B#######B###########################B#######B##", "#B#########B#########################B#########B#", "#B#########B#########################B#########B#", "#B#########B#########################B#########B#", "#B#########B#########################B#########B#", "#B#########B#########################B#########B#", "#B#########B#########################B#########B#", "#B#########B#########################B#########B#", "#B#########B#########################B#########B#", "#B#########B#########################B#########B#", "BBBBBBCBBBBBBBBCCBB###########BBDDBBBBBBBBDBBBBBB")
                    .aisle("BCCCCCCCCCCCCCCBBFFFFFFFEFFFFFFFBBDDDDDDDDDDDDDDB", "#C####C####C#########################D####D####D#", "#C####C####C#########################D####D####D#", "#C####C####C#########################D####D####D#", "#C####C####C#########################D####D####D#", "#C####C####C#########################D####D####D#", "#C####C####C#########################D####D####D#", "#C####C####C#########################D####D####D#", "#C####C####C#########################D####D####D#", "#C####C####C#########################D####D####D#", "##C###C###C###########################D###D###D##", "##C###C###C###########################D###D###D##", "##C###C###C###########################D###D###D##", "##C###C###C###########################D###D###D##", "##C###C###C###########################D###D###D##", "##C###C###C###########################D###D###D##", "##C###C###C###########################D###D###D##", "###C##C##C#############################D##D##D###", "###C##C##C#############################D##D##D###", "###C##C##C#############################D##D##D###", "###C##C##C#############################D##D##D###", "###C##C##C#############################D##D##D###", "####C#C#C###############################D#D#D####", "####C#C#C###############################D#D#D####", "####C#C#C###############################D#D#D####", "#####CCC#################################DDD#####", "#####CCCE###############################EDDD#####", "#####CCCE###############################EDDD#####", "#####CCCE###############################EDDD#####", "#####CCC#################################DDD#####", "####C#C#C###############################D#D#D####", "####C#C#C###############################D#D#D####", "####C#C#C###############################D#D#D####", "###C##C##C#############################D##D##D###", "###C##C##C#############################D##D##D###", "###C##C##C#############################D##D##D###", "###C##C##C#############################D##D##D###", "###C##C##C#############################D##D##D###", "##C###C###C###########################D###D###D##", "##C###C###C###########################D###D###D##", "##C###C###C###########################D###D###D##", "##C###C###C###########################D###D###D##", "##C###C###C###########################D###D###D##", "##C###C###C###########################D###D###D##", "##C###C###C###########################D###D###D##", "#C####C####C#########################D####D####D#", "#C####C####C#########################D####D####D#", "#C####C####C#########################D####D####D#", "#C####C####C#########################D####D####D#", "#C####C####C#########################D####D####D#", "#C####C####C#########################D####D####D#", "#C####C####C#########################D####D####D#", "#C####C####C#########################D####D####D#", "#C####C####C#########################D####D####D#", "CCCCCCCCCCCCCCCBB###############BBDDDDDDDDDDDDDDD")
                    .aisle("BBBBBBCBBBBBBBBFFFFFFFFFEFFFFFFFFFBBBBBBBBDBBBBBB", "#B#########B#########################B#########B#", "#B#########B#########################B#########B#", "#B#########B#########################B#########B#", "#B#########B#########################B#########B#", "#B#########B#########################B#########B#", "#B#########B#########################B#########B#", "#B#########B#########################B#########B#", "#B#########B#########################B#########B#", "#B#########B#########################B#########B#", "##B#######B###########################B#######B##", "##B#######B###########################B#######B##", "##B#######B###########################B#######B##", "##B#######B###########################B#######B##", "##B#######B###########################B#######B##", "##B#######B###########################B#######B##", "##B#######B###########################B#######B##", "###B#####B#############################B#####B###", "###B#####B#############################B#####B###", "###B#####B#############################B#####B###", "###B#####B#############################B#####B###", "###B#####B#############################B#####B###", "####B###B###############################B###B####", "####B###B###############################B###B####", "####B###B###############################B###B####", "#####BCB#################################BDB#####", "#####BCB#################################BDB#####", "#####BCB#################################BDB#####", "#####BCB#################################BDB#####", "#####BCB#################################BDB#####", "####B###B###############################B###B####", "####B###B###############################B###B####", "####B###B###############################B###B####", "###B#####B#############################B#####B###", "###B#####B#############################B#####B###", "###B#####B#############################B#####B###", "###B#####B#############################B#####B###", "###B#####B#############################B#####B###", "##B#######B###########################B#######B##", "##B#######B###########################B#######B##", "##B#######B###########################B#######B##", "##B#######B###########################B#######B##", "##B#######B###########################B#######B##", "##B#######B###########################B#######B##", "##B#######B###########################B#######B##", "#B#########B#########################B#########B#", "#B#########B#########################B#########B#", "#B#########B#########################B#########B#", "#B#########B#########################B#########B#", "#B#########B#########################B#########B#", "#B#########B#########################B#########B#", "#B#########B#########################B#########B#", "#B#########B#########################B#########B#", "#B#########B#########################B#########B#", "BBBBBBCBBBBBBBB###################BBBBBBBBDBBBBBB")
                    .aisle("#BBBBBCBBBBBFFFFFFFFFFFFEFFFFFFFFFFFFBBBBBDBBBBB#", "##B#######B###########################B#######B##", "##B#######B###########################B#######B##", "##B#######B###########################B#######B##", "##B#######B###########################B#######B##", "##B#######B###########################B#######B##", "##B#######B###########################B#######B##", "##B#######B###########################B#######B##", "##B#######B###########################B#######B##", "##B#######B###########################B#######B##", "###B#####B#############################B#####B###", "###B#####B#############################B#####B###", "###B#####B#############################B#####B###", "###B#####B#############################B#####B###", "###B#####B#############################B#####B###", "###B#####B#############################B#####B###", "###B#####B#############################B#####B###", "####B###B###############################B###B####", "####B###B###############################B###B####", "####B###B###############################B###B####", "####B###B###############################B###B####", "####B###B###############################B###B####", "#####BCB#################################BDB#####", "#####BCB#################################BDB#####", "#####BCB#################################BDB#####", "#################################################", "######G###################################H######", "######G###################################H######", "######G###################################H######", "#################################################", "#####BCB#################################BDB#####", "#####BCB#################################BDB#####", "#####BCB#################################BDB#####", "####B###B###############################B###B####", "####B###B###############################B###B####", "####B###B###############################B###B####", "####B###B###############################B###B####", "####B###B###############################B###B####", "###B#####B#############################B#####B###", "###B#####B#############################B#####B###", "###B#####B#############################B#####B###", "###B#####B#############################B#####B###", "###B#####B#############################B#####B###", "###B#####B#############################B#####B###", "###B#####B#############################B#####B###", "##B#######B###########################B#######B##", "##B#######B###########################B#######B##", "##B#######B###########################B#######B##", "##B#######B###########################B#######B##", "##B#######B###########################B#######B##", "##B#######B###########################B#######B##", "##B#######B###########################B#######B##", "##B#######B###########################B#######B##", "##B#######B###########################B#######B##", "#BBBBBCBBBBB#########################BBBBBDBBBBB#")
                    .aisle("#BBBBBCBBBBBFFFFFFFFFFFFEFFFFFFFFFFFFBBBBBDBBBBB#", "##B#######B###########################B#######B##", "##B#######B###########################B#######B##", "##B#######B###########################B#######B##", "##B#######B###########################B#######B##", "##B#######B###########################B#######B##", "##B#######B###########################B#######B##", "##B#######B###########################B#######B##", "##B#######B###########################B#######B##", "##B#######B###########################B#######B##", "###BB###BB#############################BB###BB###", "###BB###BB#############################BB###BB###", "###BB###BB#############################BB###BB###", "###BB###BB#############################BB###BB###", "###BB###BB#############################BB###BB###", "###BB###BB#############################BB###BB###", "###BB###BB#############################BB###BB###", "#####BCB#################################BDB#####", "#####BCB#################################BDB#####", "#####BCB#################################BDB#####", "#####BCB#################################BDB#####", "#####BCB#################################BDB#####", "#################################################", "#################################################", "#################################################", "#################################################", "#####G#####################################H#####", "#####G#####################################H#####", "#####G#####################################H#####", "#################################################", "#################################################", "#################################################", "#################################################", "#####BCB#################################BDB#####", "#####BCB#################################BDB#####", "#####BCB#################################BDB#####", "#####BCB#################################BDB#####", "#####BCB#################################BDB#####", "###BB###BB#############################BB###BB###", "###BB###BB#############################BB###BB###", "###BB###BB#############################BB###BB###", "###BB###BB#############################BB###BB###", "###BB###BB#############################BB###BB###", "###BB###BB#############################BB###BB###", "###BB###BB#############################BB###BB###", "##B#######B###########################B#######B##", "##B#######B###########################B#######B##", "##B#######B###########################B#######B##", "##B#######B###########################B#######B##", "##B#######B###########################B#######B##", "##B#######B###########################B#######B##", "##B#######B###########################B#######B##", "##B#######B###########################B#######B##", "##B#######B###########################B#######B##", "#BBBBBCBBBBB#########################BBBBBDBBBBB#")
                    .aisle("##BBBBCBBBBFFFFFFFFFFFFFEFFFFFFFFFFFFFBBBBDBBBB##", "###BB###BB#############################BB###BB###", "###BB###BB#############################BB###BB###", "###BB###BB#############################BB###BB###", "###BB###BB#############################BB###BB###", "###BB###BB#############################BB###BB###", "###BB###BB#############################BB###BB###", "###BB###BB#############################BB###BB###", "###BB###BB#############################BB###BB###", "###BB###BB#############################BB###BB###", "#####BCB#################################BDB#####", "#####BCB#################################BDB#####", "#####BCB#################################BDB#####", "#####BCB#################################BDB#####", "#####BCB#################################BDB#####", "#####BCB#################################BDB#####", "#####BCB#################################BDB#####", "#################################################", "#################################################", "#################################################", "#################################################", "#################################################", "#################################################", "#################################################", "#################################################", "#################################################", "#####G#####################################H#####", "#####G#####################################H#####", "#####G#####################################H#####", "#################################################", "#################################################", "#################################################", "#################################################", "#################################################", "#################################################", "#################################################", "#################################################", "#################################################", "#####BCB#################################BDB#####", "#####BCB#################################BDB#####", "#####BCB#################################BDB#####", "#####BCB#################################BDB#####", "#####BCB#################################BDB#####", "#####BCB#################################BDB#####", "#####BCB#################################BDB#####", "###BB###BB#############################BB###BB###", "###BB###BB#############################BB###BB###", "###BB###BB#############################BB###BB###", "###BB###BB#############################BB###BB###", "###BB###BB#############################BB###BB###", "###BB###BB#############################BB###BB###", "###BB###BB#############################BB###BB###", "###BB###BB#############################BB###BB###", "###BB###BB#############################BB###BB###", "##BBBBCBBBB###########################BBBBDBBBB##")
                    .aisle("###BBBCBBBFFFFFFFFFFFFFFEFFFFFFFFFFFFFFBBBDBBB###", "#####BCB#################################BDB#####", "#####BCB#################################BDB#####", "#####BCB#################################BDB#####", "#####BCB#################################BDB#####", "#####BCB#################################BDB#####", "#####BCB#################################BDB#####", "#####BCB#################################BDB#####", "#####BCB#################################BDB#####", "#####BCB#################################BDB#####", "#################################################", "#################################################", "#################################################", "#################################################", "#################################################", "#################################################", "#################################################", "#################################################", "#################################################", "#################################################", "#################################################", "#################################################", "#################################################", "#################################################", "#################################################", "#################################################", "####G#######################################H####", "####G#######################################H####", "####G#######################################H####", "#################################################", "#################################################", "#################################################", "#################################################", "#################################################", "#################################################", "#################################################", "#################################################", "#################################################", "#################################################", "#################################################", "#################################################", "#################################################", "#################################################", "#################################################", "#################################################", "#####BCB#################################BDB#####", "#####BCB#################################BDB#####", "#####BCB#################################BDB#####", "#####BCB#################################BDB#####", "#####BCB#################################BDB#####", "#####BCB#################################BDB#####", "#####BCB#################################BDB#####", "#####BCB#################################BDB#####", "#####BCB#################################BDB#####", "###BBBCBBB#############################BBBDBBB###")
                    .aisle("#####BCBFFFFFFFFFFFFFFFFEFFFFFFFFFFFFFFFFBDB#####", "#################################################", "#################################################", "#################################################", "#################################################", "#################################################", "#################################################", "#################################################", "#################################################", "#################################################", "#################################################", "#################################################", "#################################################", "#################################################", "#################################################", "#################################################", "#################################################", "#################################################", "#################################################", "#################################################", "#################################################", "#################################################", "#################################################", "#################################################", "#################################################", "#################################################", "####G#######################################H####", "####G#######################################H####", "####G#######################################H####", "#################################################", "#################################################", "#################################################", "#################################################", "#################################################", "#################################################", "#################################################", "#################################################", "#################################################", "#################################################", "#################################################", "#################################################", "#################################################", "#################################################", "#################################################", "#################################################", "#################################################", "#################################################", "#################################################", "#################################################", "#################################################", "#################################################", "#################################################", "#################################################", "#################################################", "#####BCB#################################BDB#####")
                    .aisle("#####BCBFFFFFFFFFFFFFFFFEFFFFFFFFFFFFFFFFBDB#####", "#################################################", "#################################################", "#################################################", "#################################################", "#################################################", "#################################################", "#################################################", "#################################################", "#################################################", "#################################################", "#################################################", "#################################################", "#################################################", "#################################################", "#################################################", "#################################################", "#################################################", "#################################################", "#################################################", "#################################################", "#################################################", "#################################################", "#################################################", "#################################################", "#################################################", "###G#########################################H###", "###G#########################################H###", "###G#########################################H###", "#################################################", "#################################################", "#################################################", "#################################################", "#################################################", "#################################################", "#################################################", "#################################################", "#################################################", "#################################################", "#################################################", "#################################################", "#################################################", "#################################################", "#################################################", "#################################################", "#################################################", "#################################################", "#################################################", "#################################################", "#################################################", "#################################################", "#################################################", "#################################################", "#################################################", "#####BCB#################################BDB#####")
                    .aisle("#####BCBFFFFFFFFFFFFFFFFEFFFFFFFFFFFFFFFFBDB#####", "#################################################", "#################################################", "#################################################", "#################################################", "#################################################", "#################################################", "#################################################", "#################################################", "#################################################", "#################################################", "#################################################", "#################################################", "#################################################", "#################################################", "#################################################", "#################################################", "#################################################", "#################################################", "#################################################", "#################################################", "#################################################", "#################################################", "#################################################", "#################################################", "#################################################", "###G#########################################H###", "###G#########################################H###", "###G#########################################H###", "#################################################", "#################################################", "#################################################", "#################################################", "#################################################", "#################################################", "#################################################", "#################################################", "#################################################", "#################################################", "#################################################", "#################################################", "#################################################", "#################################################", "#################################################", "#################################################", "#################################################", "#################################################", "#################################################", "#################################################", "#################################################", "#################################################", "#################################################", "#################################################", "#################################################", "#####BCB#################################BDB#####")
                    .aisle("####BCBFFFFFFFFFFFFFFFFFEFFFFFFFFFFFFFFFFFBDB####", "#################################################", "#################################################", "#################################################", "#################################################", "#################################################", "#################################################", "#################################################", "#################################################", "#################################################", "#################################################", "#################################################", "#################################################", "#################################################", "#################################################", "#################################################", "#################################################", "#################################################", "#################################################", "#################################################", "#################################################", "#################################################", "#################################################", "#################################################", "#################################################", "#################################################", "###G#########################################H###", "###G#########################################H###", "###G#########################################H###", "#################################################", "#################################################", "#################################################", "#################################################", "#################################################", "#################################################", "#################################################", "#################################################", "#################################################", "#################################################", "#################################################", "#################################################", "#################################################", "#################################################", "#################################################", "#################################################", "#################################################", "#################################################", "#################################################", "#################################################", "#################################################", "#################################################", "#################################################", "#################################################", "#################################################", "####BCB###################################BDB####")
                    .aisle("####BCBFFFFFFFFFFFFFFFFFEFFFFFFFFFFFFFFFFFBDB####", "#################################################", "#################################################", "#################################################", "#################################################", "#################################################", "#################################################", "#################################################", "#################################################", "#################################################", "#################################################", "#################################################", "#################################################", "#################################################", "#################################################", "#################################################", "#################################################", "#################################################", "#################################################", "#################################################", "#################################################", "#################################################", "#################################################", "#################################################", "#################################################", "#################################################", "##G###########################################H##", "##G###########################################H##", "##G###########################################H##", "#################################################", "#################################################", "#################################################", "#################################################", "#################################################", "#################################################", "#################################################", "#################################################", "#################################################", "#################################################", "#################################################", "#################################################", "#################################################", "#################################################", "#################################################", "#################################################", "#################################################", "#################################################", "#################################################", "#################################################", "#################################################", "#################################################", "#################################################", "#################################################", "#################################################", "####BCB###################################BDB####")
                    .aisle("###BCBFFFFFFFFFFFFFFFFFFEFFFFFFFFFFFFFFFFFFBDB###", "#################################################", "#################################################", "#################################################", "#################################################", "#################################################", "#################################################", "#################################################", "#################################################", "#################################################", "#################################################", "#################################################", "#################################################", "#################################################", "#################################################", "#################################################", "#################################################", "#################################################", "#################################################", "#################################################", "#################################################", "#################################################", "#################################################", "#################################################", "#################################################", "#################################################", "##G###########################################H##", "##G###########################################H##", "##G###########################################H##", "#################################################", "#################################################", "#################################################", "#################################################", "#################################################", "#################################################", "#################################################", "#################################################", "#################################################", "#################################################", "#################################################", "#################################################", "#################################################", "#################################################", "#################################################", "#################################################", "#################################################", "#################################################", "#################################################", "#################################################", "#################################################", "#################################################", "#################################################", "#################################################", "#################################################", "###BCB#####################################BDB###")
                    .aisle("###BCBFFFFFFFFFFFFFFFFFFEFFFFFFFFFFFFFFFFFFBDB###", "#################################################", "#################################################", "#################################################", "#################################################", "#################################################", "#################################################", "#################################################", "#################################################", "#################################################", "#################################################", "#################################################", "#################################################", "#################################################", "#################################################", "#################################################", "#################################################", "#################################################", "#################################################", "#################################################", "#################################################", "#################################################", "#################################################", "#################################################", "#################################################", "#################################################", "##G###########################################H##", "##G###########################################H##", "##G###########################################H##", "#################################################", "#################################################", "#################################################", "#################################################", "#################################################", "#################################################", "#################################################", "#################################################", "#################################################", "#################################################", "#################################################", "#################################################", "#################################################", "#################################################", "#################################################", "#################################################", "#################################################", "#################################################", "#################################################", "#################################################", "#################################################", "#################################################", "#################################################", "#################################################", "#################################################", "###BCB#####################################BDB###")
                    .aisle("##BCBFFFFFFFFFFFFFFFFFFFEFFFFFFFFFFFFFFFFFFFBDB##", "#################################################", "#################################################", "#################################################", "#################################################", "#################################################", "#################################################", "#################################################", "#################################################", "#################################################", "#################################################", "#################################################", "#################################################", "#################################################", "#################################################", "#################################################", "#################################################", "#################################################", "#################################################", "#################################################", "#################################################", "#################################################", "#################################################", "#################################################", "#################################################", "#################################################", "##G###########################################H##", "##G###########################################H##", "##G###########################################H##", "#################################################", "#################################################", "#################################################", "#################################################", "#################################################", "#################################################", "#################################################", "#################################################", "#################################################", "#################################################", "#################################################", "#################################################", "#################################################", "#################################################", "#################################################", "#################################################", "#################################################", "#################################################", "#################################################", "#################################################", "#################################################", "#################################################", "#################################################", "#################################################", "#################################################", "##BCB#######################################BDB##")
                    .aisle("##BCBFFFFFFFFFFFFFFFFFFFEFFFFFFFFFFFFFFFFFFFBDB##", "#################################################", "#################################################", "#################################################", "#################################################", "#################################################", "#################################################", "#################################################", "#################################################", "#################################################", "#################################################", "#################################################", "#################################################", "#################################################", "#################################################", "#################################################", "#################################################", "#################################################", "#################################################", "#################################################", "#################################################", "#################################################", "#################################################", "#################################################", "#################################################", "#################################################", "##G###########################################H##", "##G###########################################H##", "##G###########################################H##", "#################################################", "#################################################", "#################################################", "#################################################", "#################################################", "#################################################", "#################################################", "#################################################", "#################################################", "#################################################", "#################################################", "#################################################", "#################################################", "#################################################", "#################################################", "#################################################", "#################################################", "#################################################", "#################################################", "#################################################", "#################################################", "#################################################", "#################################################", "#################################################", "#################################################", "##BCB#######################################BDB##")
                    .aisle("#BCBFFFFFFFFFFFFFFFFFFFFEFFFFFFFFFFFFFFFFFFFFBDB#", "#################################################", "#################################################", "#################################################", "#################################################", "#################################################", "#################################################", "#################################################", "#################################################", "#################################################", "#################################################", "#################################################", "#################################################", "#################################################", "#################################################", "#################################################", "#################################################", "#################################################", "#################################################", "#################################################", "#################################################", "#################################################", "#################################################", "#################################################", "#################################################", "#################################################", "#G#############################################H#", "#G#############################################H#", "#G#############################################H#", "#################################################", "#################################################", "#################################################", "#################################################", "#################################################", "#################################################", "#################################################", "#################################################", "#################################################", "#################################################", "#################################################", "#################################################", "#################################################", "#################################################", "#################################################", "#################################################", "#################################################", "#################################################", "#################################################", "#################################################", "#################################################", "#################################################", "#################################################", "#################################################", "#################################################", "#BCB#########################################BDB#")
                    .aisle("BCBFFFFFFFFFFFFFFFFFFFFFEFFFFFFFFFFFFFFFFFFFFFBDB", "#################################################", "#################################################", "#################################################", "#################################################", "#################################################", "#################################################", "#################################################", "#################################################", "#################################################", "#################################################", "#################################################", "#################################################", "#################################################", "#################################################", "#################################################", "#################################################", "#################################################", "#################################################", "#################################################", "#################################################", "#################################################", "#################################################", "#################################################", "#################################################", "#################################################", "#G#############################################H#", "#G#############################################H#", "#G#############################################H#", "#################################################", "#################################################", "#################################################", "#################################################", "#################################################", "#################################################", "#################################################", "#################################################", "#################################################", "#################################################", "#################################################", "#################################################", "#################################################", "#################################################", "#################################################", "#################################################", "#################################################", "#################################################", "#################################################", "#################################################", "#################################################", "#################################################", "#################################################", "#################################################", "#################################################", "BCB###########################################BDB")
                    .aisle("BCBFFFFFFFFFFFFFFFFFFFFFEFFFFFFFFFFFFFFFFFFFFFBDB", "#################################################", "#################################################", "#################################################", "#################################################", "#################################################", "#################################################", "#################################################", "#################################################", "#################################################", "#################################################", "#################################################", "#################################################", "#################################################", "#################################################", "#################################################", "#################################################", "#################################################", "#################################################", "#################################################", "#################################################", "#################################################", "#################################################", "#################################################", "#################################################", "#################################################", "#G#############################################H#", "#G#############################################H#", "#G#############################################H#", "#################################################", "#################################################", "#################################################", "#################################################", "#################################################", "#################################################", "#################################################", "#################################################", "#################################################", "#################################################", "#################################################", "#################################################", "#################################################", "#################################################", "#################################################", "#################################################", "#################################################", "#################################################", "#################################################", "#################################################", "#################################################", "#################################################", "#################################################", "#################################################", "#################################################", "BCB###########################################BDB")
                    .aisle("BBGGGGGGGGGGGGGGGGGGGGGGIHHHHHHHHHHHHHHHHHHHHHHBB", "#################################################", "#################################################", "#################################################", "#################################################", "#################################################", "#################################################", "#################################################", "#################################################", "#################################################", "#################################################", "#################################################", "#################################################", "#################################################", "#################################################", "#################################################", "#################################################", "#################################################", "#################################################", "#################################################", "#################################################", "#################################################", "#################################################", "#################################################", "#################################################", "#################################################", "#G#############################################H#", "#G#############################################H#", "#G#############################################H#", "#################################################", "#################################################", "#################################################", "#################################################", "#################################################", "#################################################", "#################################################", "#################################################", "#################################################", "#################################################", "#################################################", "#################################################", "#################################################", "#################################################", "#################################################", "#################################################", "#################################################", "#################################################", "#################################################", "#################################################", "#################################################", "#################################################", "#################################################", "#################################################", "#################################################", "BBB###########################################BBB")
                    .aisle("BJBFFFFFFFFFFFFFFFFFFFFFKFFFFFFFFFFFFFFFFFFFFFB#B", "#################################################", "#################################################", "#################################################", "#################################################", "#################################################", "#################################################", "#################################################", "#################################################", "#################################################", "#################################################", "#################################################", "#################################################", "#################################################", "#################################################", "#################################################", "#################################################", "#################################################", "#################################################", "#################################################", "#################################################", "#################################################", "#################################################", "#################################################", "#################################################", "#################################################", "#G#############################################H#", "#G#############################################H#", "#G#############################################H#", "#################################################", "#################################################", "#################################################", "#################################################", "#################################################", "#################################################", "#################################################", "#################################################", "#################################################", "#################################################", "#################################################", "#################################################", "#################################################", "#################################################", "#################################################", "#################################################", "#################################################", "#################################################", "#################################################", "#################################################", "#################################################", "#################################################", "#################################################", "#################################################", "#################################################", "BJB###########################################B#B")
                    .aisle("BJBFFFFFFFFFFFFFFFFFFFFFKFFFFFFFFFFFFFFFFFFFFFB#B", "#################################################", "#################################################", "#################################################", "#################################################", "#################################################", "#################################################", "#################################################", "#################################################", "#################################################", "#################################################", "#################################################", "#################################################", "#################################################", "#################################################", "#################################################", "#################################################", "#################################################", "#################################################", "#################################################", "#################################################", "#################################################", "#################################################", "#################################################", "#################################################", "#################################################", "#G#############################################H#", "#G#############################################H#", "#G#############################################H#", "#################################################", "#################################################", "#################################################", "#################################################", "#################################################", "#################################################", "#################################################", "#################################################", "#################################################", "#################################################", "#################################################", "#################################################", "#################################################", "#################################################", "#################################################", "#################################################", "#################################################", "#################################################", "#################################################", "#################################################", "#################################################", "#################################################", "#################################################", "#################################################", "#################################################", "BJB###########################################B#B")
                    .aisle("#BJBFFFFFFFFFFFFFFFFFFFFKFFFFFFFFFFFFFFFFFFFFB#B#", "#################################################", "#################################################", "#################################################", "#################################################", "#################################################", "#################################################", "#################################################", "#################################################", "#################################################", "#################################################", "#################################################", "#################################################", "#################################################", "#################################################", "#################################################", "#################################################", "#################################################", "#################################################", "#################################################", "#################################################", "#################################################", "#################################################", "#################################################", "#################################################", "#################################################", "#G#############################################H#", "#G#############################################H#", "#G#############################################H#", "#################################################", "#################################################", "#################################################", "#################################################", "#################################################", "#################################################", "#################################################", "#################################################", "#################################################", "#################################################", "#################################################", "#################################################", "#################################################", "#################################################", "#################################################", "#################################################", "#################################################", "#################################################", "#################################################", "#################################################", "#################################################", "#################################################", "#################################################", "#################################################", "#################################################", "#BJB#########################################B#B#")
                    .aisle("##BJBFFFFFFFFFFFFFFFFFFFKFFFFFFFFFFFFFFFFFFFB#B##", "#################################################", "#################################################", "#################################################", "#################################################", "#################################################", "#################################################", "#################################################", "#################################################", "#################################################", "#################################################", "#################################################", "#################################################", "#################################################", "#################################################", "#################################################", "#################################################", "#################################################", "#################################################", "#################################################", "#################################################", "#################################################", "#################################################", "#################################################", "#################################################", "#################################################", "##G###########################################H##", "##G###########################################H##", "##G###########################################H##", "#################################################", "#################################################", "#################################################", "#################################################", "#################################################", "#################################################", "#################################################", "#################################################", "#################################################", "#################################################", "#################################################", "#################################################", "#################################################", "#################################################", "#################################################", "#################################################", "#################################################", "#################################################", "#################################################", "#################################################", "#################################################", "#################################################", "#################################################", "#################################################", "#################################################", "##BJB#######################################B#B##")
                    .aisle("##BJBFFFFFFFFFFFFFFFFFFFKFFFFFFFFFFFFFFFFFFFB#B##", "#################################################", "#################################################", "#################################################", "#################################################", "#################################################", "#################################################", "#################################################", "#################################################", "#################################################", "#################################################", "#################################################", "#################################################", "#################################################", "#################################################", "#################################################", "#################################################", "#################################################", "#################################################", "#################################################", "#################################################", "#################################################", "#################################################", "#################################################", "#################################################", "#################################################", "##G###########################################H##", "##G###########################################H##", "##G###########################################H##", "#################################################", "#################################################", "#################################################", "#################################################", "#################################################", "#################################################", "#################################################", "#################################################", "#################################################", "#################################################", "#################################################", "#################################################", "#################################################", "#################################################", "#################################################", "#################################################", "#################################################", "#################################################", "#################################################", "#################################################", "#################################################", "#################################################", "#################################################", "#################################################", "#################################################", "##BJB#######################################B#B##")
                    .aisle("###BJBFFFFFFFFFFFFFFFFFFKFFFFFFFFFFFFFFFFFFB#B###", "#################################################", "#################################################", "#################################################", "#################################################", "#################################################", "#################################################", "#################################################", "#################################################", "#################################################", "#################################################", "#################################################", "#################################################", "#################################################", "#################################################", "#################################################", "#################################################", "#################################################", "#################################################", "#################################################", "#################################################", "#################################################", "#################################################", "#################################################", "#################################################", "#################################################", "##G###########################################H##", "##G###########################################H##", "##G###########################################H##", "#################################################", "#################################################", "#################################################", "#################################################", "#################################################", "#################################################", "#################################################", "#################################################", "#################################################", "#################################################", "#################################################", "#################################################", "#################################################", "#################################################", "#################################################", "#################################################", "#################################################", "#################################################", "#################################################", "#################################################", "#################################################", "#################################################", "#################################################", "#################################################", "#################################################", "###BJB#####################################B#B###")
                    .aisle("###BJBFFFFFFFFFFFFFFFFFFKFFFFFFFFFFFFFFFFFFB#B###", "#################################################", "#################################################", "#################################################", "#################################################", "#################################################", "#################################################", "#################################################", "#################################################", "#################################################", "#################################################", "#################################################", "#################################################", "#################################################", "#################################################", "#################################################", "#################################################", "#################################################", "#################################################", "#################################################", "#################################################", "#################################################", "#################################################", "#################################################", "#################################################", "#################################################", "##G###########################################H##", "##G###########################################H##", "##G###########################################H##", "#################################################", "#################################################", "#################################################", "#################################################", "#################################################", "#################################################", "#################################################", "#################################################", "#################################################", "#################################################", "#################################################", "#################################################", "#################################################", "#################################################", "#################################################", "#################################################", "#################################################", "#################################################", "#################################################", "#################################################", "#################################################", "#################################################", "#################################################", "#################################################", "#################################################", "###BJB#####################################B#B###")
